Workbook

Sheet 일별,주차별(무신사)
D2: 10
D3: 광고 집행일 | E3: =COUNTIFS($C$7:$C1003, "<>0", $B$7:$B1003, "<>") -> 87
B4: * 플랫폼별 효율 | C4: MUSINSA | R4: * 플랫폼별 효율 | S4: MUSINSA
B5: * 일자별 효율 | C5: =SUM(C$7:C1003) -> 5400910 | D5: =SUM(D$7:D1003) -> 104658103 | E5: =IFERROR(D5/C5,0) -> 19.377865 | G5: =SUMIF($A$7:$A$1003,$D$2,G$7:G1003) -> 248743 | H5: =SUMIF($A$7:$A$1003,$D$2,H$7:H1003) -> 7462 | I5: =SUMIF($A$7:$A$1003,$D$2,I$7:I1003) -> 238 | J5: =IFERROR( I5/H5,0) -> 0.031894934 | K5: =IFERROR(H5/G5,0) -> 0.029998834 | N5: =SUMIF($A$7:$A$1003,N$7:N1003) -> 0 | O5: =IFERROR( N5/C5,0) -> 0 | R5: * 주차별 효율 | S5: =SUM(S$7:S1003) -> 5400910 | T5: =SUM(T$7:T1003) -> 104658103 | U5: =IFERROR(T5/S5,0) -> 19.377865 | W5: =SUM(W$7:W1003) -> 1514683 | X5: =SUM(X$7:X1003) -> 36493 | Y5: =IFERROR(X5/W5,0) -> 0.02409283 | AB5: =SUM(AB$7:AB1003) -> 775821631 | AC5: =IFERROR( AB5/S5,0) -> 143.64647
C6: 광고비 | D6: 전환 매출 | E6: 전환율(금액) | F6: DOD | G6: 노출 | H6: 클릭 | I6: 전환 구매 | J6: 클릭대비 구매율 | K6: CTR | L6: DOD | N6: 장바구니 | O6: 미전환율 | S6: 광고비 | T6: 전환 매출 | U6: 전환율 | V6: DOD | W6: 노출 | X6: 클릭 | Y6: CTR | Z6: DOD | AB6: 장바구니 | AC6: 미전환율
A7: =MONTH(B7) -> 3 | B7: =IFERROR(__xludf.DUMMYFUNCTION("SORT(UNIQUE(FILTER('무신사 메타 광고'!D3:D1003,'무신사 메타 광고'!D3:D1003 <> """")))"),46111) -> 46111 | C7: =IF($C$4="", SUMIFS('무신사 메타 광고'!$L:$L, '무신사 메타 광고'!$D:$D, $B7), SUMIFS('무신사 메타 광고'!$L:$L, '무신사 메타 광고'!$I:$I, $C$4, '무신사 메타 광고'!$D:$D, $B7)) -> 10559 | D7: =IF($C$4="", SUMIFS('무신사 메타 광고'!$V:$V, '무신사 메타 광고'!$D:$D, $B7), SUMIFS('무신사 메타 광고'!$V:$V,'무신사 메타 광고'!$I:$I,$C$4,'무신사 메타 광고'!$D:$D,$B7)) -> 0 | E7: =IFERROR(D7/C7,0) -> 0 | G7: =IF($C$4="", SUMIFS('무신사 메타 광고'!$K:$K, '무신사 메타 광고'!$D:$D, $B7), SUMIFS('무신사 메타 광고'!$K:$K,'무신사 메타 광고'!$I:$I,$C$4,'무신사 메타 광고'!D:D,$B7)) -> 2591 | H7: =IF($C$4="", SUMIFS('무신사 메타 광고'!$N:$N, '무신사 메타 광고'!$D:$D, $B7),SUMIFS('무신사 메타 광고'!$N:$N,'무신사 메타 광고'!$I:$I,$C$4,'무신사 메타 광고'!$D:$D,$B7)) -> 39 | I7: =IF($C$4="", SUMIFS('무신사 메타 광고'!$U:$U, '무신사 메타 광고'!$D:$D, $B7),SUMIFS('무신사 메타 광고'!$U:$U,'무신사 메타 광고'!$I:$I,$C$4,'무신사 메타 광고'!$D:$D,$B7)) -> 0 | J7: =IFERROR( I7/H7,0) -> 0 | K7: =IFERROR(H7/G7,0) -> 0.015052103 | L7: =IF( IFERROR(IF(K6=0, 0, (K7 - K6) / K6), 0)=0," ",IFERROR(IF(K6=0, 0, (K7 - K6) / K6), 0)) | N7: =IF($C$4="", SUMIFS('무신사 메타 광고'!$X:$X, '무신사 메타 광고'!$D:$D, $B7),SUMIFS('무신사 메타 광고'!$X:$X,'무신사 메타 광고'!I:I,$C$4,'무신사 메타 광고'!D:D,$B7)) -> 0 | O7: =IFERROR( N7/(N7+D7),0 ) -> 0 | R7: =IFERROR(__xludf.DUMMYFUNCTION("SORT(UNIQUE(FILTER('무신사 메타 광고'!C3:C1003,'무신사 메타 광고'!C3:C1003 <> """")))"),"26년 3월 6주차") -> 26년 3월 6주차 | S7: =IF($S$4="", SUMIFS('무신사 메타 광고'!$L:$L, '무신사 메타 광고'!$C:$C, $R7),SUMIFS('무신사 메타 광고'!$L:$L,'무신사 메타 광고'!$I:$I,$S$4,'무신사 메타 광고'!$C:$C,$R7)) -> 67546 | T7: =IF($S$4="", SUMIFS('무신사 메타 광고'!$V:$V, '무신사 메타 광고'!$C:$C, $R7),SUMIFS('무신사 메타 광고'!$V:$V,'무신사 메타 광고'!$I:$I,$S$4,'무신사 메타 광고'!$C:$C,$R7)) -> 402300 | U7: =IFERROR(T7/S7,0) -> 5.9559411 | W7: =IF($S$4="", SUMIFS('무신사 메타 광고'!$K:$K, '무신사 메타 광고'!$C:$C, $R7),SUMIFS('무신사 메타 광고'!$K:$K,'무신사 메타 광고'!$I:$I,$S$4,'무신사 메타 광고'!$C:$C,$R7)) -> 19190 | X7: =IF($S$4="", SUMIFS('무신사 메타 광고'!$N:$N, '무신사 메타 광고'!$C:$C, $R7),SUMIFS('무신사 메타 광고'!$N:$N,'무신사 메타 광고'!$I:$I,$S$4,'무신사 메타 광고'!$C:$C,$R7)) -> 341 | Y7: =IFERROR(X7/W7,0) -> 0.017769672 | AB7: =IF($S$4="", SUMIFS('무신사 메타 광고'!$X:$X, '무신사 메타 광고'!$C:$C, $R7),SUMIFS('무신사 메타 광고'!$X:$X,'무신사 메타 광고'!$I:$I,$S$4,'무신사 메타 광고'!$C:$C,$R7)) -> 3537550 | AC7: =IFERROR( AB7/(AB7+T7),0 ) -> 0.89788951
A8: =MONTH(B8) -> 3 | B8: =IFERROR(__xludf.DUMMYFUNCTION("""COMPUTED_VALUE"""),46112) -> 46112 | C8: =IF($C$4="", SUMIFS('무신사 메타 광고'!$L:$L, '무신사 메타 광고'!$D:$D, $B8), SUMIFS('무신사 메타 광고'!$L:$L, '무신사 메타 광고'!$I:$I, $C$4, '무신사 메타 광고'!$D:$D, $B8)) -> 56987 | D8: =IF($C$4="", SUMIFS('무신사 메타 광고'!$V:$V, '무신사 메타 광고'!$D:$D, $B8), SUMIFS('무신사 메타 광고'!$V:$V,'무신사 메타 광고'!$I:$I,$C$4,'무신사 메타 광고'!$D:$D,$B8)) -> 402300 | E8: =IFERROR(D8/C8,0) -> 7.0595048 | F8: =IF( IFERROR(IF(E7=0, 0, (E8 - E7) / E7), 0)=0," ",IFERROR(IF(E7=0, 0, (E8 - E7) / E7), 0)) | G8: =IF($C$4="", SUMIFS('무신사 메타 광고'!$K:$K, '무신사 메타 광고'!$D:$D, $B8), SUMIFS('무신사 메타 광고'!$K:$K,'무신사 메타 광고'!$I:$I,$C$4,'무신사 메타 광고'!D:D,$B8)) -> 16599 | H8: =IF($C$4="", SUMIFS('무신사 메타 광고'!$N:$N, '무신사 메타 광고'!$D:$D, $B8),SUMIFS('무신사 메타 광고'!$N:$N,'무신사 메타 광고'!$I:$I,$C$4,'무신사 메타 광고'!$D:$D,$B8)) -> 302 | I8: =IF($C$4="", SUMIFS('무신사 메타 광고'!$U:$U, '무신사 메타 광고'!$D:$D, $B8),SUMIFS('무신사 메타 광고'!$U:$U,'무신사 메타 광고'!$I:$I,$C$4,'무신사 메타 광고'!$D:$D,$B8)) -> 3 | J8: =IFERROR( I8/H8,0) -> 0.0099337748 | K8: =IFERROR(H8/G8,0) -> 0.018193867 | L8: =IF( IFERROR(IF(K7=0, 0, (K8 - K7) / K7), 0)=0," ",IFERROR(IF(K7=0, 0, (K8 - K7) / K7), 0)) -> 0.20872589 | N8: =IF($C$4="", SUMIFS('무신사 메타 광고'!$X:$X, '무신사 메타 광고'!$D:$D, $B8),SUMIFS('무신사 메타 광고'!$X:$X,'무신사 메타 광고'!I:I,$C$4,'무신사 메타 광고'!D:D,$B8)) -> 3537550 | O8: =IFERROR( N8/(N8+D8),0 ) -> 0.89788951 | R8: =IFERROR(__xludf.DUMMYFUNCTION("""COMPUTED_VALUE"""),"26년 4월 1주차") -> 26년 4월 1주차 | S8: =IF($S$4="", SUMIFS('무신사 메타 광고'!$L:$L, '무신사 메타 광고'!$C:$C, $R8),SUMIFS('무신사 메타 광고'!L:L,'무신사 메타 광고'!$I:$I,$S$4,'무신사 메타 광고'!$C:$C,$R8)) -> 183198 | T8: =IF($S$4="", SUMIFS('무신사 메타 광고'!$V:$V, '무신사 메타 광고'!$C:$C, $R8),SUMIFS('무신사 메타 광고'!$V:$V,'무신사 메타 광고'!$I:$I,$S$4,'무신사 메타 광고'!$C:$C,$R8)) -> 2650950 | U8: =IFERROR(T8/S8,0) -> 14.470409 | V8: =IF( IFERROR(IF(U7=0, 0, (U8 - U7) / U7), 0)=0," ",IFERROR(IF(U7=0, 0, (U8 - U7) / U7), 0)) -> 1.4295756 | W8: =IF($S$4="", SUMIFS('무신사 메타 광고'!$K:$K, '무신사 메타 광고'!$C:$C, $R8),SUMIFS('무신사 메타 광고'!$K:$K,'무신사 메타 광고'!$I:$I,$S$4,'무신사 메타 광고'!$C:$C,$R8)) -> 62927 | X8: =IF($S$4="", SUMIFS('무신사 메타 광고'!$N:$N, '무신사 메타 광고'!$C:$C, $R8),SUMIFS('무신사 메타 광고'!$N:$N,'무신사 메타 광고'!$I:$I,$S$4,'무신사 메타 광고'!$C:$C,$R8)) -> 984 | Y8: =IFERROR(X8/W8,0) -> 0.015637167 | Z8: =IF( IFERROR(IF(Y7=0, 0, (Y8 - Y7) / Y7), 0)=0," ",IFERROR(IF(Y7=0, 0, (Y8 - Y7) / Y7), 0)) -> -0.12000812 | AB8: =IF($S$4="", SUMIFS('무신사 메타 광고'!$X:$X, '무신사 메타 광고'!$C:$C, $R8),SUMIFS('무신사 메타 광고'!$X:$X,'무신사 메타 광고'!$I:$I,$S$4,'무신사 메타 광고'!$C:$C,$R8)) -> 16166900 | AC8: =IFERROR( AB8/(AB8+T8),0 ) -> 0.85912578
A9: =MONTH(B9) -> 4 | B9: =IFERROR(__xludf.DUMMYFUNCTION("""COMPUTED_VALUE"""),46113) -> 46113 | C9: =IF($C$4="", SUMIFS('무신사 메타 광고'!$L:$L, '무신사 메타 광고'!$D:$D, $B9), SUMIFS('무신사 메타 광고'!$L:$L, '무신사 메타 광고'!$I:$I, $C$4, '무신사 메타 광고'!$D:$D, $B9)) -> 38018 | D9: =IF($C$4="", SUMIFS('무신사 메타 광고'!$V:$V, '무신사 메타 광고'!$D:$D, $B9), SUMIFS('무신사 메타 광고'!$V:$V,'무신사 메타 광고'!$I:$I,$C$4,'무신사 메타 광고'!$D:$D,$B9)) -> 517800 | E9: =IFERROR(D9/C9,0) -> 13.619864 | F9: =IF( IFERROR(IF(E8=0, 0, (E9 - E8) / E8), 0)=0," ",IFERROR(IF(E8=0, 0, (E9 - E8) / E8), 0)) -> 0.92929457 | G9: =IF($C$4="", SUMIFS('무신사 메타 광고'!$K:$K, '무신사 메타 광고'!$D:$D, $B9), SUMIFS('무신사 메타 광고'!$K:$K,'무신사 메타 광고'!$I:$I,$C$4,'무신사 메타 광고'!D:D,$B9)) -> 12306 | H9: =IF($C$4="", SUMIFS('무신사 메타 광고'!$N:$N, '무신사 메타 광고'!$D:$D, $B9),SUMIFS('무신사 메타 광고'!$N:$N,'무신사 메타 광고'!$I:$I,$C$4,'무신사 메타 광고'!$D:$D,$B9)) -> 213 | I9: =IF($C$4="", SUMIFS('무신사 메타 광고'!$U:$U, '무신사 메타 광고'!$D:$D, $B9),SUMIFS('무신사 메타 광고'!$U:$U,'무신사 메타 광고'!$I:$I,$C$4,'무신사 메타 광고'!$D:$D,$B9)) -> 4 | J9: =IFERROR( I9/H9,0) -> 0.018779343 | K9: =IFERROR(H9/G9,0) -> 0.01730863 | L9: =IF( IFERROR(IF(K8=0, 0, (K9 - K8) / K8), 0)=0," ",IFERROR(IF(K8=0, 0, (K9 - K8) / K8), 0)) -> -0.0486558 | N9: =IF($C$4="", SUMIFS('무신사 메타 광고'!$X:$X, '무신사 메타 광고'!$D:$D, $B9),SUMIFS('무신사 메타 광고'!$X:$X,'무신사 메타 광고'!I:I,$C$4,'무신사 메타 광고'!D:D,$B9)) -> 573350 | O9: =IFERROR( N9/(N9+D9),0 ) -> 0.5254548 | R9: =IFERROR(__xludf.DUMMYFUNCTION("""COMPUTED_VALUE"""),"26년 4월 2주차") -> 26년 4월 2주차 | S9: =IF($S$4="", SUMIFS('무신사 메타 광고'!$L:$L, '무신사 메타 광고'!$C:$C, $R9),SUMIFS('무신사 메타 광고'!L:L,'무신사 메타 광고'!$I:$I,$S$4,'무신사 메타 광고'!$C:$C,$R9)) -> 280943 | T9: =IF($S$4="", SUMIFS('무신사 메타 광고'!$V:$V, '무신사 메타 광고'!$C:$C, $R9),SUMIFS('무신사 메타 광고'!$V:$V,'무신사 메타 광고'!$I:$I,$S$4,'무신사 메타 광고'!$C:$C,$R9)) -> 9366900 | U9: =IFERROR(T9/S9,0) -> 33.340927 | V9: =IF( IFERROR(IF(U8=0, 0, (U9 - U8) / U8), 0)=0," ",IFERROR(IF(U8=0, 0, (U9 - U8) / U8), 0)) -> 1.3040763 | W9: =IF($S$4="", SUMIFS('무신사 메타 광고'!$K:$K, '무신사 메타 광고'!$C:$C, $R9),SUMIFS('무신사 메타 광고'!$K:$K,'무신사 메타 광고'!$I:$I,$S$4,'무신사 메타 광고'!$C:$C,$R9)) -> 83052 | X9: =IF($S$4="", SUMIFS('무신사 메타 광고'!$N:$N, '무신사 메타 광고'!$C:$C, $R9),SUMIFS('무신사 메타 광고'!$N:$N,'무신사 메타 광고'!$I:$I,$S$4,'무신사 메타 광고'!$C:$C,$R9)) -> 1393 | Y9: =IFERROR(X9/W9,0) -> 0.016772624 | Z9: =IF( IFERROR(IF(Y8=0, 0, (Y9 - Y8) / Y8), 0)=0," ",IFERROR(IF(Y8=0, 0, (Y9 - Y8) / Y8), 0)) -> 0.072612738 | AB9: =IF($S$4="", SUMIFS('무신사 메타 광고'!$X:$X, '무신사 메타 광고'!$C:$C, $R9),SUMIFS('무신사 메타 광고'!$X:$X,'무신사 메타 광고'!$I:$I,$S$4,'무신사 메타 광고'!$C:$C,$R9)) -> 42064950 | AC9: =IFERROR( AB9/(AB9+T9),0 ) -> 0.81787744
A10: =MONTH(B10) -> 4 | B10: =IFERROR(__xludf.DUMMYFUNCTION("""COMPUTED_VALUE"""),46114) -> 46114 | C10: =IF($C$4="", SUMIFS('무신사 메타 광고'!$L:$L, '무신사 메타 광고'!$D:$D, $B10), SUMIFS('무신사 메타 광고'!$L:$L, '무신사 메타 광고'!$I:$I, $C$4, '무신사 메타 광고'!$D:$D, $B10)) -> 33267 | D10: =IF($C$4="", SUMIFS('무신사 메타 광고'!$V:$V, '무신사 메타 광고'!$D:$D, $B10), SUMIFS('무신사 메타 광고'!$V:$V,'무신사 메타 광고'!$I:$I,$C$4,'무신사 메타 광고'!$D:$D,$B10)) -> 299850 | E10: =IFERROR(D10/C10,0) -> 9.0134367 | F10: =IF( IFERROR(IF(E9=0, 0, (E10 - E9) / E9), 0)=0," ",IFERROR(IF(E9=0, 0, (E10 - E9) / E9), 0)) -> -0.33821391 | G10: =IF($C$4="", SUMIFS('무신사 메타 광고'!$K:$K, '무신사 메타 광고'!$D:$D, $B10), SUMIFS('무신사 메타 광고'!$K:$K,'무신사 메타 광고'!$I:$I,$C$4,'무신사 메타 광고'!D:D,$B10)) -> 10528 | H10: =IF($C$4="", SUMIFS('무신사 메타 광고'!$N:$N, '무신사 메타 광고'!$D:$D, $B10),SUMIFS('무신사 메타 광고'!$N:$N,'무신사 메타 광고'!$I:$I,$C$4,'무신사 메타 광고'!$D:$D,$B10)) -> 194 | I10: =IF($C$4="", SUMIFS('무신사 메타 광고'!$U:$U, '무신사 메타 광고'!$D:$D, $B10),SUMIFS('무신사 메타 광고'!$U:$U,'무신사 메타 광고'!$I:$I,$C$4,'무신사 메타 광고'!$D:$D,$B10)) -> 4 | J10: =IFERROR( I10/H10,0) -> 0.020618557 | K10: =IFERROR(H10/G10,0) -> 0.018427052 | L10: =IF( IFERROR(IF(K9=0, 0, (K10 - K9) / K9), 0)=0," ",IFERROR(IF(K9=0, 0, (K10 - K9) / K9), 0)) -> 0.064616422 | N10: =IF($C$4="", SUMIFS('무신사 메타 광고'!$X:$X, '무신사 메타 광고'!$D:$D, $B10),SUMIFS('무신사 메타 광고'!$X:$X,'무신사 메타 광고'!I:I,$C$4,'무신사 메타 광고'!D:D,$B10)) -> 2770050 | O10: =IFERROR( N10/(N10+D10),0 ) -> 0.90232581 | R10: =IFERROR(__xludf.DUMMYFUNCTION("""COMPUTED_VALUE"""),"26년 4월 3주차") -> 26년 4월 3주차 | S10: =IF($S$4="", SUMIFS('무신사 메타 광고'!$L:$L, '무신사 메타 광고'!$C:$C, $R10),SUMIFS('무신사 메타 광고'!L:L,'무신사 메타 광고'!$I:$I,$S$4,'무신사 메타 광고'!$C:$C,$R10)) -> 342136 | T10: =IF($S$4="", SUMIFS('무신사 메타 광고'!$V:$V, '무신사 메타 광고'!$C:$C, $R10),SUMIFS('무신사 메타 광고'!$V:$V,'무신사 메타 광고'!$I:$I,$S$4,'무신사 메타 광고'!$C:$C,$R10)) -> 9040200 | U10: =IFERROR(T10/S10,0) -> 26.422826 | V10: =IF( IFERROR(IF(U9=0, 0, (U10 - U9) / U9), 0)=0," ",IFERROR(IF(U9=0, 0, (U10 - U9) / U9), 0)) -> -0.20749576 | W10: =IF($S$4="", SUMIFS('무신사 메타 광고'!$K:$K, '무신사 메타 광고'!$C:$C, $R10),SUMIFS('무신사 메타 광고'!$K:$K,'무신사 메타 광고'!$I:$I,$S$4,'무신사 메타 광고'!$C:$C,$R10)) -> 92075 | X10: =IF($S$4="", SUMIFS('무신사 메타 광고'!$N:$N, '무신사 메타 광고'!$C:$C, $R10),SUMIFS('무신사 메타 광고'!$N:$N,'무신사 메타 광고'!$I:$I,$S$4,'무신사 메타 광고'!$C:$C,$R10)) -> 1977 | Y10: =IFERROR(X10/W10,0) -> 0.021471626 | Z10: =IF( IFERROR(IF(Y9=0, 0, (Y10 - Y9) / Y9), 0)=0," ",IFERROR(IF(Y9=0, 0, (Y10 - Y9) / Y9), 0)) -> 0.28015902 | AB10: =IF($S$4="", SUMIFS('무신사 메타 광고'!$X:$X, '무신사 메타 광고'!$C:$C, $R10),SUMIFS('무신사 메타 광고'!$X:$X,'무신사 메타 광고'!$I:$I,$S$4,'무신사 메타 광고'!$C:$C,$R10)) -> 91230587 | AC10: =IFERROR( AB10/(AB10+T10),0 ) -> 0.90984214
A11: =MONTH(B11) -> 4 | B11: =IFERROR(__xludf.DUMMYFUNCTION("""COMPUTED_VALUE"""),46115) -> 46115 | C11: =IF($C$4="", SUMIFS('무신사 메타 광고'!$L:$L, '무신사 메타 광고'!$D:$D, $B11), SUMIFS('무신사 메타 광고'!$L:$L, '무신사 메타 광고'!$I:$I, $C$4, '무신사 메타 광고'!$D:$D, $B11)) -> 34213 | D11: =IF($C$4="", SUMIFS('무신사 메타 광고'!$V:$V, '무신사 메타 광고'!$D:$D, $B11), SUMIFS('무신사 메타 광고'!$V:$V,'무신사 메타 광고'!$I:$I,$C$4,'무신사 메타 광고'!$D:$D,$B11)) -> 288900 | E11: =IFERROR(D11/C11,0) -> 8.4441587 | F11: =IF( IFERROR(IF(E10=0, 0, (E11 - E10) / E10), 0)=0," ",IFERROR(IF(E10=0, 0, (E11 - E10) / E10), 0)) -> -0.063158826 | G11: =IF($C$4="", SUMIFS('무신사 메타 광고'!$K:$K, '무신사 메타 광고'!$D:$D, $B11), SUMIFS('무신사 메타 광고'!$K:$K,'무신사 메타 광고'!$I:$I,$C$4,'무신사 메타 광고'!D:D,$B11)) -> 12303 | H11: =IF($C$4="", SUMIFS('무신사 메타 광고'!$N:$N, '무신사 메타 광고'!$D:$D, $B11),SUMIFS('무신사 메타 광고'!$N:$N,'무신사 메타 광고'!$I:$I,$C$4,'무신사 메타 광고'!$D:$D,$B11)) -> 166 | I11: =IF($C$4="", SUMIFS('무신사 메타 광고'!$U:$U, '무신사 메타 광고'!$D:$D, $B11),SUMIFS('무신사 메타 광고'!$U:$U,'무신사 메타 광고'!$I:$I,$C$4,'무신사 메타 광고'!$D:$D,$B11)) -> 3 | J11: =IFERROR( I11/H11,0) -> 0.018072289 | K11: =IFERROR(H11/G11,0) -> 0.013492644 | L11: =IF( IFERROR(IF(K10=0, 0, (K11 - K10) / K10), 0)=0," ",IFERROR(IF(K10=0, 0, (K11 - K10) / K10), 0)) -> -0.26778064 | N11: =IF($C$4="", SUMIFS('무신사 메타 광고'!$X:$X, '무신사 메타 광고'!$D:$D, $B11),SUMIFS('무신사 메타 광고'!$X:$X,'무신사 메타 광고'!I:I,$C$4,'무신사 메타 광고'!D:D,$B11)) -> 2613300 | O11: =IFERROR( N11/(N11+D11),0 ) -> 0.90045483 | R11: =IFERROR(__xludf.DUMMYFUNCTION("""COMPUTED_VALUE"""),"26년 4월 4주차") -> 26년 4월 4주차 | S11: =IF($S$4="", SUMIFS('무신사 메타 광고'!$L:$L, '무신사 메타 광고'!$C:$C, $R11),SUMIFS('무신사 메타 광고'!L:L,'무신사 메타 광고'!$I:$I,$S$4,'무신사 메타 광고'!$C:$C,$R11)) -> 425188 | T11: =IF($S$4="", SUMIFS('무신사 메타 광고'!$V:$V, '무신사 메타 광고'!$C:$C, $R11),SUMIFS('무신사 메타 광고'!$V:$V,'무신사 메타 광고'!$I:$I,$S$4,'무신사 메타 광고'!$C:$C,$R11)) -> 6182050 | U11: =IFERROR(T11/S11,0) -> 14.539568 | V11: =IF( IFERROR(IF(U10=0, 0, (U11 - U10) / U10), 0)=0," ",IFERROR(IF(U10=0, 0, (U11 - U10) / U10), 0)) -> -0.44973454 | W11: =IF($S$4="", SUMIFS('무신사 메타 광고'!$K:$K, '무신사 메타 광고'!$C:$C, $R11),SUMIFS('무신사 메타 광고'!$K:$K,'무신사 메타 광고'!$I:$I,$S$4,'무신사 메타 광고'!$C:$C,$R11)) -> 130204 | X11: =IF($S$4="", SUMIFS('무신사 메타 광고'!$N:$N, '무신사 메타 광고'!$C:$C, $R11),SUMIFS('무신사 메타 광고'!$N:$N,'무신사 메타 광고'!$I:$I,$S$4,'무신사 메타 광고'!$C:$C,$R11)) -> 3420 | Y11: =IFERROR(X11/W11,0) -> 0.026266474 | Z11: =IF( IFERROR(IF(Y10=0, 0, (Y11 - Y10) / Y10), 0)=0," ",IFERROR(IF(Y10=0, 0, (Y11 - Y10) / Y10), 0)) -> 0.22331088 | AB11: =IF($S$4="", SUMIFS('무신사 메타 광고'!$X:$X, '무신사 메타 광고'!$C:$C, $R11),SUMIFS('무신사 메타 광고'!$X:$X,'무신사 메타 광고'!$I:$I,$S$4,'무신사 메타 광고'!$C:$C,$R11)) -> 69550718 | AC11: =IFERROR( AB11/(AB11+T11),0 ) -> 0.91837021
A12: =MONTH(B12) -> 4 | B12: =IFERROR(__xludf.DUMMYFUNCTION("""COMPUTED_VALUE"""),46116) -> 46116 | C12: =IF($C$4="", SUMIFS('무신사 메타 광고'!$L:$L, '무신사 메타 광고'!$D:$D, $B12), SUMIFS('무신사 메타 광고'!$L:$L, '무신사 메타 광고'!$I:$I, $C$4, '무신사 메타 광고'!$D:$D, $B12)) -> 40265 | D12: =IF($C$4="", SUMIFS('무신사 메타 광고'!$V:$V, '무신사 메타 광고'!$D:$D, $B12), SUMIFS('무신사 메타 광고'!$V:$V,'무신사 메타 광고'!$I:$I,$C$4,'무신사 메타 광고'!$D:$D,$B12)) -> 705600 | E12: =IFERROR(D12/C12,0) -> 17.523904 | F12: =IF( IFERROR(IF(E11=0, 0, (E12 - E11) / E11), 0)=0," ",IFERROR(IF(E11=0, 0, (E12 - E11) / E11), 0)) -> 1.0752694 | G12: =IF($C$4="", SUMIFS('무신사 메타 광고'!$K:$K, '무신사 메타 광고'!$D:$D, $B12), SUMIFS('무신사 메타 광고'!$K:$K,'무신사 메타 광고'!$I:$I,$C$4,'무신사 메타 광고'!D:D,$B12)) -> 14446 | H12: =IF($C$4="", SUMIFS('무신사 메타 광고'!$N:$N, '무신사 메타 광고'!$D:$D, $B12),SUMIFS('무신사 메타 광고'!$N:$N,'무신사 메타 광고'!$I:$I,$C$4,'무신사 메타 광고'!$D:$D,$B12)) -> 178 | I12: =IF($C$4="", SUMIFS('무신사 메타 광고'!$U:$U, '무신사 메타 광고'!$D:$D, $B12),SUMIFS('무신사 메타 광고'!$U:$U,'무신사 메타 광고'!$I:$I,$C$4,'무신사 메타 광고'!$D:$D,$B12)) -> 5 | J12: =IFERROR( I12/H12,0) -> 0.028089888 | K12: =IFERROR(H12/G12,0) -> 0.01232175 | L12: =IF( IFERROR(IF(K11=0, 0, (K12 - K11) / K11), 0)=0," ",IFERROR(IF(K11=0, 0, (K12 - K11) / K11), 0)) -> -0.086780182 | N12: =IF($C$4="", SUMIFS('무신사 메타 광고'!$X:$X, '무신사 메타 광고'!$D:$D, $B12),SUMIFS('무신사 메타 광고'!$X:$X,'무신사 메타 광고'!I:I,$C$4,'무신사 메타 광고'!D:D,$B12)) -> 4498800 | O12: =IFERROR( N12/(N12+D12),0 ) -> 0.86442241 | R12: =IFERROR(__xludf.DUMMYFUNCTION("""COMPUTED_VALUE"""),"26년 4월 5주차") -> 26년 4월 5주차 | S12: =IF($S$4="", SUMIFS('무신사 메타 광고'!$L:$L, '무신사 메타 광고'!$C:$C, $R12),SUMIFS('무신사 메타 광고'!L:L,'무신사 메타 광고'!$I:$I,$S$4,'무신사 메타 광고'!$C:$C,$R12)) -> 238424 | T12: =IF($S$4="", SUMIFS('무신사 메타 광고'!$V:$V, '무신사 메타 광고'!$C:$C, $R12),SUMIFS('무신사 메타 광고'!$V:$V,'무신사 메타 광고'!$I:$I,$S$4,'무신사 메타 광고'!$C:$C,$R12)) -> 8232950 | U12: =IFERROR(T12/S12,0) -> 34.53071 | V12: =IF( IFERROR(IF(U11=0, 0, (U12 - U11) / U11), 0)=0," ",IFERROR(IF(U11=0, 0, (U12 - U11) / U11), 0)) -> 1.3749474 | W12: =IF($S$4="", SUMIFS('무신사 메타 광고'!$K:$K, '무신사 메타 광고'!$C:$C, $R12),SUMIFS('무신사 메타 광고'!$K:$K,'무신사 메타 광고'!$I:$I,$S$4,'무신사 메타 광고'!$C:$C,$R12)) -> 71010 | X12: =IF($S$4="", SUMIFS('무신사 메타 광고'!$N:$N, '무신사 메타 광고'!$C:$C, $R12),SUMIFS('무신사 메타 광고'!$N:$N,'무신사 메타 광고'!$I:$I,$S$4,'무신사 메타 광고'!$C:$C,$R12)) -> 2024 | Y12: =IFERROR(X12/W12,0) -> 0.028503028 | Z12: =IF( IFERROR(IF(Y11=0, 0, (Y12 - Y11) / Y11), 0)=0," ",IFERROR(IF(Y11=0, 0, (Y12 - Y11) / Y11), 0)) -> 0.085148604 | AB12: =IF($S$4="", SUMIFS('무신사 메타 광고'!$X:$X, '무신사 메타 광고'!$C:$C, $R12),SUMIFS('무신사 메타 광고'!$X:$X,'무신사 메타 광고'!$I:$I,$S$4,'무신사 메타 광고'!$C:$C,$R12)) -> 42718350 | AC12: =IFERROR( AB12/(AB12+T12),0 ) -> 0.83841531
A13: =MONTH(B13) -> 4 | B13: =IFERROR(__xludf.DUMMYFUNCTION("""COMPUTED_VALUE"""),46117) -> 46117 | C13: =IF($C$4="", SUMIFS('무신사 메타 광고'!$L:$L, '무신사 메타 광고'!$D:$D, $B13), SUMIFS('무신사 메타 광고'!$L:$L, '무신사 메타 광고'!$I:$I, $C$4, '무신사 메타 광고'!$D:$D, $B13)) -> 37435 | D13: =IF($C$4="", SUMIFS('무신사 메타 광고'!$V:$V, '무신사 메타 광고'!$D:$D, $B13), SUMIFS('무신사 메타 광고'!$V:$V,'무신사 메타 광고'!$I:$I,$C$4,'무신사 메타 광고'!$D:$D,$B13)) -> 838800 | E13: =IFERROR(D13/C13,0) -> 22.406839 | F13: =IF( IFERROR(IF(E12=0, 0, (E13 - E12) / E12), 0)=0," ",IFERROR(IF(E12=0, 0, (E13 - E12) / E12), 0)) -> 0.27864421 | G13: =IF($C$4="", SUMIFS('무신사 메타 광고'!$K:$K, '무신사 메타 광고'!$D:$D, $B13), SUMIFS('무신사 메타 광고'!$K:$K,'무신사 메타 광고'!$I:$I,$C$4,'무신사 메타 광고'!D:D,$B13)) -> 13344 | H13: =IF($C$4="", SUMIFS('무신사 메타 광고'!$N:$N, '무신사 메타 광고'!$D:$D, $B13),SUMIFS('무신사 메타 광고'!$N:$N,'무신사 메타 광고'!$I:$I,$C$4,'무신사 메타 광고'!$D:$D,$B13)) -> 233 | I13: =IF($C$4="", SUMIFS('무신사 메타 광고'!$U:$U, '무신사 메타 광고'!$D:$D, $B13),SUMIFS('무신사 메타 광고'!$U:$U,'무신사 메타 광고'!$I:$I,$C$4,'무신사 메타 광고'!$D:$D,$B13)) -> 9 | J13: =IFERROR( I13/H13,0) -> 0.038626609 | K13: =IFERROR(H13/G13,0) -> 0.017461031 | L13: =IF( IFERROR(IF(K12=0, 0, (K13 - K12) / K12), 0)=0," ",IFERROR(IF(K12=0, 0, (K13 - K12) / K12), 0)) -> 0.4170902 | N13: =IF($C$4="", SUMIFS('무신사 메타 광고'!$X:$X, '무신사 메타 광고'!$D:$D, $B13),SUMIFS('무신사 메타 광고'!$X:$X,'무신사 메타 광고'!I:I,$C$4,'무신사 메타 광고'!D:D,$B13)) -> 5711400 | O13: =IFERROR( N13/(N13+D13),0 ) -> 0.87194284 | R13: =IFERROR(__xludf.DUMMYFUNCTION("""COMPUTED_VALUE"""),"26년 5월 1주차") -> 26년 5월 1주차 | S13: =IF($S$4="", SUMIFS('무신사 메타 광고'!$L:$L, '무신사 메타 광고'!$C:$C, $R13),SUMIFS('무신사 메타 광고'!L:L,'무신사 메타 광고'!$I:$I,$S$4,'무신사 메타 광고'!$C:$C,$R13)) -> 178537 | T13: =IF($S$4="", SUMIFS('무신사 메타 광고'!$V:$V, '무신사 메타 광고'!$C:$C, $R13),SUMIFS('무신사 메타 광고'!$V:$V,'무신사 메타 광고'!$I:$I,$S$4,'무신사 메타 광고'!$C:$C,$R13)) -> 1833300 | U13: =IFERROR(T13/S13,0) -> 10.26846 | V13: =IF( IFERROR(IF(U12=0, 0, (U13 - U12) / U12), 0)=0," ",IFERROR(IF(U12=0, 0, (U13 - U12) / U12), 0)) -> -0.70262819 | W13: =IF($S$4="", SUMIFS('무신사 메타 광고'!$K:$K, '무신사 메타 광고'!$C:$C, $R13),SUMIFS('무신사 메타 광고'!$K:$K,'무신사 메타 광고'!$I:$I,$S$4,'무신사 메타 광고'!$C:$C,$R13)) -> 63197 | X13: =IF($S$4="", SUMIFS('무신사 메타 광고'!$N:$N, '무신사 메타 광고'!$C:$C, $R13),SUMIFS('무신사 메타 광고'!$N:$N,'무신사 메타 광고'!$I:$I,$S$4,'무신사 메타 광고'!$C:$C,$R13)) -> 1116 | Y13: =IFERROR(X13/W13,0) -> 0.017659066 | Z13: =IF( IFERROR(IF(Y12=0, 0, (Y13 - Y12) / Y12), 0)=0," ",IFERROR(IF(Y12=0, 0, (Y13 - Y12) / Y12), 0)) -> -0.38044946 | AB13: =IF($S$4="", SUMIFS('무신사 메타 광고'!$X:$X, '무신사 메타 광고'!$C:$C, $R13),SUMIFS('무신사 메타 광고'!$X:$X,'무신사 메타 광고'!$I:$I,$S$4,'무신사 메타 광고'!$C:$C,$R13)) -> 15156050 | AC13: =IFERROR( AB13/(AB13+T13),0 ) -> 0.89209122
A14: =MONTH(B14) -> 4 | B14: =IFERROR(__xludf.DUMMYFUNCTION("""COMPUTED_VALUE"""),46118) -> 46118 | C14: =IF($C$4="", SUMIFS('무신사 메타 광고'!$L:$L, '무신사 메타 광고'!$D:$D, $B14), SUMIFS('무신사 메타 광고'!$L:$L, '무신사 메타 광고'!$I:$I, $C$4, '무신사 메타 광고'!$D:$D, $B14)) -> 42728 | D14: =IF($C$4="", SUMIFS('무신사 메타 광고'!$V:$V, '무신사 메타 광고'!$D:$D, $B14), SUMIFS('무신사 메타 광고'!$V:$V,'무신사 메타 광고'!$I:$I,$C$4,'무신사 메타 광고'!$D:$D,$B14)) -> 2371500 | E14: =IFERROR(D14/C14,0) -> 55.502247 | F14: =IF( IFERROR(IF(E13=0, 0, (E14 - E13) / E13), 0)=0," ",IFERROR(IF(E13=0, 0, (E14 - E13) / E13), 0)) -> 1.4770227 | G14: =IF($C$4="", SUMIFS('무신사 메타 광고'!$K:$K, '무신사 메타 광고'!$D:$D, $B14), SUMIFS('무신사 메타 광고'!$K:$K,'무신사 메타 광고'!$I:$I,$C$4,'무신사 메타 광고'!D:D,$B14)) -> 15234 | H14: =IF($C$4="", SUMIFS('무신사 메타 광고'!$N:$N, '무신사 메타 광고'!$D:$D, $B14),SUMIFS('무신사 메타 광고'!$N:$N,'무신사 메타 광고'!$I:$I,$C$4,'무신사 메타 광고'!$D:$D,$B14)) -> 231 | I14: =IF($C$4="", SUMIFS('무신사 메타 광고'!$U:$U, '무신사 메타 광고'!$D:$D, $B14),SUMIFS('무신사 메타 광고'!$U:$U,'무신사 메타 광고'!$I:$I,$C$4,'무신사 메타 광고'!$D:$D,$B14)) -> 17 | J14: =IFERROR( I14/H14,0) -> 0.073593074 | K14: =IFERROR(H14/G14,0) -> 0.01516345 | L14: =IF( IFERROR(IF(K13=0, 0, (K14 - K13) / K13), 0)=0," ",IFERROR(IF(K13=0, 0, (K14 - K13) / K13), 0)) -> -0.13158335 | N14: =IF($C$4="", SUMIFS('무신사 메타 광고'!$X:$X, '무신사 메타 광고'!$D:$D, $B14),SUMIFS('무신사 메타 광고'!$X:$X,'무신사 메타 광고'!I:I,$C$4,'무신사 메타 광고'!D:D,$B14)) -> 3280650 | O14: =IFERROR( N14/(N14+D14),0 ) -> 0.58042515 | R14: =IFERROR(__xludf.DUMMYFUNCTION("""COMPUTED_VALUE"""),"26년 5월 2주차") -> 26년 5월 2주차 | S14: =IF($S$4="", SUMIFS('무신사 메타 광고'!$L:$L, '무신사 메타 광고'!$C:$C, $R14),SUMIFS('무신사 메타 광고'!L:L,'무신사 메타 광고'!$I:$I,$S$4,'무신사 메타 광고'!$C:$C,$R14)) -> 415285 | T14: =IF($S$4="", SUMIFS('무신사 메타 광고'!$V:$V, '무신사 메타 광고'!$C:$C, $R14),SUMIFS('무신사 메타 광고'!$V:$V,'무신사 메타 광고'!$I:$I,$S$4,'무신사 메타 광고'!$C:$C,$R14)) -> 7511400 | U14: =IFERROR(T14/S14,0) -> 18.087338 | V14: =IF( IFERROR(IF(U13=0, 0, (U14 - U13) / U13), 0)=0," ",IFERROR(IF(U13=0, 0, (U14 - U13) / U13), 0)) -> 0.76144602 | W14: =IF($S$4="", SUMIFS('무신사 메타 광고'!$K:$K, '무신사 메타 광고'!$C:$C, $R14),SUMIFS('무신사 메타 광고'!$K:$K,'무신사 메타 광고'!$I:$I,$S$4,'무신사 메타 광고'!$C:$C,$R14)) -> 130556 | X14: =IF($S$4="", SUMIFS('무신사 메타 광고'!$N:$N, '무신사 메타 광고'!$C:$C, $R14),SUMIFS('무신사 메타 광고'!$N:$N,'무신사 메타 광고'!$I:$I,$S$4,'무신사 메타 광고'!$C:$C,$R14)) -> 3592 | Y14: =IFERROR(X14/W14,0) -> 0.027513098 | Z14: =IF( IFERROR(IF(Y13=0, 0, (Y14 - Y13) / Y13), 0)=0," ",IFERROR(IF(Y13=0, 0, (Y14 - Y13) / Y13), 0)) -> 0.55801545 | AB14: =IF($S$4="", SUMIFS('무신사 메타 광고'!$X:$X, '무신사 메타 광고'!$C:$C, $R14),SUMIFS('무신사 메타 광고'!$X:$X,'무신사 메타 광고'!$I:$I,$S$4,'무신사 메타 광고'!$C:$C,$R14)) -> 83946200 | AC14: =IFERROR( AB14/(AB14+T14),0 ) -> 0.91787014
A15: =MONTH(B15) -> 4 | B15: =IFERROR(__xludf.DUMMYFUNCTION("""COMPUTED_VALUE"""),46119) -> 46119 | C15: =IF($C$4="", SUMIFS('무신사 메타 광고'!$L:$L, '무신사 메타 광고'!$D:$D, $B15), SUMIFS('무신사 메타 광고'!$L:$L, '무신사 메타 광고'!$I:$I, $C$4, '무신사 메타 광고'!$D:$D, $B15)) -> 42728 | D15: =IF($C$4="", SUMIFS('무신사 메타 광고'!$V:$V, '무신사 메타 광고'!$D:$D, $B15), SUMIFS('무신사 메타 광고'!$V:$V,'무신사 메타 광고'!$I:$I,$C$4,'무신사 메타 광고'!$D:$D,$B15)) -> 1170900 | E15: =IFERROR(D15/C15,0) -> 27.403576 | F15: =IF( IFERROR(IF(E14=0, 0, (E15 - E14) / E14), 0)=0," ",IFERROR(IF(E14=0, 0, (E15 - E14) / E14), 0)) -> -0.50626186 | G15: =IF($C$4="", SUMIFS('무신사 메타 광고'!$K:$K, '무신사 메타 광고'!$D:$D, $B15), SUMIFS('무신사 메타 광고'!$K:$K,'무신사 메타 광고'!$I:$I,$C$4,'무신사 메타 광고'!D:D,$B15)) -> 14736 | H15: =IF($C$4="", SUMIFS('무신사 메타 광고'!$N:$N, '무신사 메타 광고'!$D:$D, $B15),SUMIFS('무신사 메타 광고'!$N:$N,'무신사 메타 광고'!$I:$I,$C$4,'무신사 메타 광고'!$D:$D,$B15)) -> 229 | I15: =IF($C$4="", SUMIFS('무신사 메타 광고'!$U:$U, '무신사 메타 광고'!$D:$D, $B15),SUMIFS('무신사 메타 광고'!$U:$U,'무신사 메타 광고'!$I:$I,$C$4,'무신사 메타 광고'!$D:$D,$B15)) -> 9 | J15: =IFERROR( I15/H15,0) -> 0.03930131 | K15: =IFERROR(H15/G15,0) -> 0.015540174 | L15: =IF( IFERROR(IF(K14=0, 0, (K15 - K14) / K14), 0)=0," ",IFERROR(IF(K14=0, 0, (K15 - K14) / K14), 0)) -> 0.024844184 | N15: =IF($C$4="", SUMIFS('무신사 메타 광고'!$X:$X, '무신사 메타 광고'!$D:$D, $B15),SUMIFS('무신사 메타 광고'!$X:$X,'무신사 메타 광고'!I:I,$C$4,'무신사 메타 광고'!D:D,$B15)) -> 6283800 | O15: =IFERROR( N15/(N15+D15),0 ) -> 0.84293131 | R15: =IFERROR(__xludf.DUMMYFUNCTION("""COMPUTED_VALUE"""),"26년 5월 3주차") -> 26년 5월 3주차 | S15: =IF($S$4="", SUMIFS('무신사 메타 광고'!$L:$L, '무신사 메타 광고'!$C:$C, $R15),SUMIFS('무신사 메타 광고'!L:L,'무신사 메타 광고'!$I:$I,$S$4,'무신사 메타 광고'!$C:$C,$R15)) -> 442645 | T15: =IF($S$4="", SUMIFS('무신사 메타 광고'!$V:$V, '무신사 메타 광고'!$C:$C, $R15),SUMIFS('무신사 메타 광고'!$V:$V,'무신사 메타 광고'!$I:$I,$S$4,'무신사 메타 광고'!$C:$C,$R15)) -> 4472700 | U15: =IFERROR(T15/S15,0) -> 10.104486 | V15: =IF( IFERROR(IF(U14=0, 0, (U15 - U14) / U14), 0)=0," ",IFERROR(IF(U14=0, 0, (U15 - U14) / U14), 0)) -> -0.44135031 | W15: =IF($S$4="", SUMIFS('무신사 메타 광고'!$K:$K, '무신사 메타 광고'!$C:$C, $R15),SUMIFS('무신사 메타 광고'!$K:$K,'무신사 메타 광고'!$I:$I,$S$4,'무신사 메타 광고'!$C:$C,$R15)) -> 155208 | X15: =IF($S$4="", SUMIFS('무신사 메타 광고'!$N:$N, '무신사 메타 광고'!$C:$C, $R15),SUMIFS('무신사 메타 광고'!$N:$N,'무신사 메타 광고'!$I:$I,$S$4,'무신사 메타 광고'!$C:$C,$R15)) -> 2443 | Y15: =IFERROR(X15/W15,0) -> 0.015740168 | Z15: =IF( IFERROR(IF(Y14=0, 0, (Y15 - Y14) / Y14), 0)=0," ",IFERROR(IF(Y14=0, 0, (Y15 - Y14) / Y14), 0)) -> -0.42790273 | AB15: =IF($S$4="", SUMIFS('무신사 메타 광고'!$X:$X, '무신사 메타 광고'!$C:$C, $R15),SUMIFS('무신사 메타 광고'!$X:$X,'무신사 메타 광고'!$I:$I,$S$4,'무신사 메타 광고'!$C:$C,$R15)) -> 29517150 | AC15: =IFERROR( AB15/(AB15+T15),0 ) -> 0.86841072
A16: =MONTH(B16) -> 4 | B16: =IFERROR(__xludf.DUMMYFUNCTION("""COMPUTED_VALUE"""),46120) -> 46120 | C16: =IF($C$4="", SUMIFS('무신사 메타 광고'!$L:$L, '무신사 메타 광고'!$D:$D, $B16), SUMIFS('무신사 메타 광고'!$L:$L, '무신사 메타 광고'!$I:$I, $C$4, '무신사 메타 광고'!$D:$D, $B16)) -> 37351 | D16: =IF($C$4="", SUMIFS('무신사 메타 광고'!$V:$V, '무신사 메타 광고'!$D:$D, $B16), SUMIFS('무신사 메타 광고'!$V:$V,'무신사 메타 광고'!$I:$I,$C$4,'무신사 메타 광고'!$D:$D,$B16)) -> 423000 | E16: =IFERROR(D16/C16,0) -> 11.324998 | F16: =IF( IFERROR(IF(E15=0, 0, (E16 - E15) / E15), 0)=0," ",IFERROR(IF(E15=0, 0, (E16 - E15) / E15), 0)) -> -0.58673284 | G16: =IF($C$4="", SUMIFS('무신사 메타 광고'!$K:$K, '무신사 메타 광고'!$D:$D, $B16), SUMIFS('무신사 메타 광고'!$K:$K,'무신사 메타 광고'!$I:$I,$C$4,'무신사 메타 광고'!D:D,$B16)) -> 12456 | H16: =IF($C$4="", SUMIFS('무신사 메타 광고'!$N:$N, '무신사 메타 광고'!$D:$D, $B16),SUMIFS('무신사 메타 광고'!$N:$N,'무신사 메타 광고'!$I:$I,$C$4,'무신사 메타 광고'!$D:$D,$B16)) -> 219 | I16: =IF($C$4="", SUMIFS('무신사 메타 광고'!$U:$U, '무신사 메타 광고'!$D:$D, $B16),SUMIFS('무신사 메타 광고'!$U:$U,'무신사 메타 광고'!$I:$I,$C$4,'무신사 메타 광고'!$D:$D,$B16)) -> 4 | J16: =IFERROR( I16/H16,0) -> 0.01826484 | K16: =IFERROR(H16/G16,0) -> 0.017581888 | L16: =IF( IFERROR(IF(K15=0, 0, (K16 - K15) / K15), 0)=0," ",IFERROR(IF(K15=0, 0, (K16 - K15) / K15), 0)) -> 0.13138299 | N16: =IF($C$4="", SUMIFS('무신사 메타 광고'!$X:$X, '무신사 메타 광고'!$D:$D, $B16),SUMIFS('무신사 메타 광고'!$X:$X,'무신사 메타 광고'!I:I,$C$4,'무신사 메타 광고'!D:D,$B16)) -> 3962700 | O16: =IFERROR( N16/(N16+D16),0 ) -> 0.90355017 | R16: =IFERROR(__xludf.DUMMYFUNCTION("""COMPUTED_VALUE"""),"26년 5월 4주차") -> 26년 5월 4주차 | S16: =IF($S$4="", SUMIFS('무신사 메타 광고'!$L:$L, '무신사 메타 광고'!$C:$C, $R16),SUMIFS('무신사 메타 광고'!L:L,'무신사 메타 광고'!$I:$I,$S$4,'무신사 메타 광고'!$C:$C,$R16)) -> 408966 | T16: =IF($S$4="", SUMIFS('무신사 메타 광고'!$V:$V, '무신사 메타 광고'!$C:$C, $R16),SUMIFS('무신사 메타 광고'!$V:$V,'무신사 메타 광고'!$I:$I,$S$4,'무신사 메타 광고'!$C:$C,$R16)) -> 4690650 | U16: =IFERROR(T16/S16,0) -> 11.469535 | V16: =IF( IFERROR(IF(U15=0, 0, (U16 - U15) / U15), 0)=0," ",IFERROR(IF(U15=0, 0, (U16 - U15) / U15), 0)) -> 0.13509345 | W16: =IF($S$4="", SUMIFS('무신사 메타 광고'!$K:$K, '무신사 메타 광고'!$C:$C, $R16),SUMIFS('무신사 메타 광고'!$K:$K,'무신사 메타 광고'!$I:$I,$S$4,'무신사 메타 광고'!$C:$C,$R16)) -> 115739 | X16: =IF($S$4="", SUMIFS('무신사 메타 광고'!$N:$N, '무신사 메타 광고'!$C:$C, $R16),SUMIFS('무신사 메타 광고'!$N:$N,'무신사 메타 광고'!$I:$I,$S$4,'무신사 메타 광고'!$C:$C,$R16)) -> 3091 | Y16: =IFERROR(X16/W16,0) -> 0.026706642 | Z16: =IF( IFERROR(IF(Y15=0, 0, (Y16 - Y15) / Y15), 0)=0," ",IFERROR(IF(Y15=0, 0, (Y16 - Y15) / Y15), 0)) -> 0.69671897 | AB16: =IF($S$4="", SUMIFS('무신사 메타 광고'!$X:$X, '무신사 메타 광고'!$C:$C, $R16),SUMIFS('무신사 메타 광고'!$X:$X,'무신사 메타 광고'!$I:$I,$S$4,'무신사 메타 광고'!$C:$C,$R16)) -> 74454800 | AC16: =IFERROR( AB16/(AB16+T16),0 ) -> 0.9407338
A17: =MONTH(B17) -> 4 | B17: =IFERROR(__xludf.DUMMYFUNCTION("""COMPUTED_VALUE"""),46121) -> 46121 | C17: =IF($C$4="", SUMIFS('무신사 메타 광고'!$L:$L, '무신사 메타 광고'!$D:$D, $B17), SUMIFS('무신사 메타 광고'!$L:$L, '무신사 메타 광고'!$I:$I, $C$4, '무신사 메타 광고'!$D:$D, $B17)) -> 39361 | D17: =IF($C$4="", SUMIFS('무신사 메타 광고'!$V:$V, '무신사 메타 광고'!$D:$D, $B17), SUMIFS('무신사 메타 광고'!$V:$V,'무신사 메타 광고'!$I:$I,$C$4,'무신사 메타 광고'!$D:$D,$B17)) -> 1653300 | E17: =IFERROR(D17/C17,0) -> 42.003506 | F17: =IF( IFERROR(IF(E16=0, 0, (E17 - E16) / E16), 0)=0," ",IFERROR(IF(E16=0, 0, (E17 - E16) / E16), 0)) -> 2.7089195 | G17: =IF($C$4="", SUMIFS('무신사 메타 광고'!$K:$K, '무신사 메타 광고'!$D:$D, $B17), SUMIFS('무신사 메타 광고'!$K:$K,'무신사 메타 광고'!$I:$I,$C$4,'무신사 메타 광고'!D:D,$B17)) -> 13183 | H17: =IF($C$4="", SUMIFS('무신사 메타 광고'!$N:$N, '무신사 메타 광고'!$D:$D, $B17),SUMIFS('무신사 메타 광고'!$N:$N,'무신사 메타 광고'!$I:$I,$C$4,'무신사 메타 광고'!$D:$D,$B17)) -> 207 | I17: =IF($C$4="", SUMIFS('무신사 메타 광고'!$U:$U, '무신사 메타 광고'!$D:$D, $B17),SUMIFS('무신사 메타 광고'!$U:$U,'무신사 메타 광고'!$I:$I,$C$4,'무신사 메타 광고'!$D:$D,$B17)) -> 14 | J17: =IFERROR( I17/H17,0) -> 0.06763285 | K17: =IFERROR(H17/G17,0) -> 0.015702041 | L17: =IF( IFERROR(IF(K16=0, 0, (K17 - K16) / K16), 0)=0," ",IFERROR(IF(K16=0, 0, (K17 - K16) / K16), 0)) -> -0.10691956 | N17: =IF($C$4="", SUMIFS('무신사 메타 광고'!$X:$X, '무신사 메타 광고'!$D:$D, $B17),SUMIFS('무신사 메타 광고'!$X:$X,'무신사 메타 광고'!I:I,$C$4,'무신사 메타 광고'!D:D,$B17)) -> 6111000 | O17: =IFERROR( N17/(N17+D17),0 ) -> 0.78706387 | R17: =IFERROR(__xludf.DUMMYFUNCTION("""COMPUTED_VALUE"""),"26년 5월 5주차") -> 26년 5월 5주차 | S17: =IF($S$4="", SUMIFS('무신사 메타 광고'!$L:$L, '무신사 메타 광고'!$C:$C, $R17),SUMIFS('무신사 메타 광고'!L:L,'무신사 메타 광고'!$I:$I,$S$4,'무신사 메타 광고'!$C:$C,$R17)) -> 412130 | T17: =IF($S$4="", SUMIFS('무신사 메타 광고'!$V:$V, '무신사 메타 광고'!$C:$C, $R17),SUMIFS('무신사 메타 광고'!$V:$V,'무신사 메타 광고'!$I:$I,$S$4,'무신사 메타 광고'!$C:$C,$R17)) -> 6228250 | U17: =IFERROR(T17/S17,0) -> 15.112343 | V17: =IF( IFERROR(IF(U16=0, 0, (U17 - U16) / U16), 0)=0," ",IFERROR(IF(U16=0, 0, (U17 - U16) / U16), 0)) -> 0.31760727 | W17: =IF($S$4="", SUMIFS('무신사 메타 광고'!$K:$K, '무신사 메타 광고'!$C:$C, $R17),SUMIFS('무신사 메타 광고'!$K:$K,'무신사 메타 광고'!$I:$I,$S$4,'무신사 메타 광고'!$C:$C,$R17)) -> 115941 | X17: =IF($S$4="", SUMIFS('무신사 메타 광고'!$N:$N, '무신사 메타 광고'!$C:$C, $R17),SUMIFS('무신사 메타 광고'!$N:$N,'무신사 메타 광고'!$I:$I,$S$4,'무신사 메타 광고'!$C:$C,$R17)) -> 2963 | Y17: =IFERROR(X17/W17,0) -> 0.025556102 | Z17: =IF( IFERROR(IF(Y16=0, 0, (Y17 - Y16) / Y16), 0)=0," ",IFERROR(IF(Y16=0, 0, (Y17 - Y16) / Y16), 0)) -> -0.043080664 | AB17: =IF($S$4="", SUMIFS('무신사 메타 광고'!$X:$X, '무신사 메타 광고'!$C:$C, $R17),SUMIFS('무신사 메타 광고'!$X:$X,'무신사 메타 광고'!$I:$I,$S$4,'무신사 메타 광고'!$C:$C,$R17)) -> 59825190 | AC17: =IFERROR( AB17/(AB17+T17),0 ) -> 0.90570892
A18: =MONTH(B18) -> 4 | B18: =IFERROR(__xludf.DUMMYFUNCTION("""COMPUTED_VALUE"""),46122) -> 46122 | C18: =IF($C$4="", SUMIFS('무신사 메타 광고'!$L:$L, '무신사 메타 광고'!$D:$D, $B18), SUMIFS('무신사 메타 광고'!$L:$L, '무신사 메타 광고'!$I:$I, $C$4, '무신사 메타 광고'!$D:$D, $B18)) -> 26040 | D18: =IF($C$4="", SUMIFS('무신사 메타 광고'!$V:$V, '무신사 메타 광고'!$D:$D, $B18), SUMIFS('무신사 메타 광고'!$V:$V,'무신사 메타 광고'!$I:$I,$C$4,'무신사 메타 광고'!$D:$D,$B18)) -> 484500 | E18: =IFERROR(D18/C18,0) -> 18.605991 | F18: =IF( IFERROR(IF(E17=0, 0, (E18 - E17) / E17), 0)=0," ",IFERROR(IF(E17=0, 0, (E18 - E17) / E17), 0)) -> -0.5570372 | G18: =IF($C$4="", SUMIFS('무신사 메타 광고'!$K:$K, '무신사 메타 광고'!$D:$D, $B18), SUMIFS('무신사 메타 광고'!$K:$K,'무신사 메타 광고'!$I:$I,$C$4,'무신사 메타 광고'!D:D,$B18)) -> 5878 | H18: =IF($C$4="", SUMIFS('무신사 메타 광고'!$N:$N, '무신사 메타 광고'!$D:$D, $B18),SUMIFS('무신사 메타 광고'!$N:$N,'무신사 메타 광고'!$I:$I,$C$4,'무신사 메타 광고'!$D:$D,$B18)) -> 112 | I18: =IF($C$4="", SUMIFS('무신사 메타 광고'!$U:$U, '무신사 메타 광고'!$D:$D, $B18),SUMIFS('무신사 메타 광고'!$U:$U,'무신사 메타 광고'!$I:$I,$C$4,'무신사 메타 광고'!$D:$D,$B18)) -> 6 | J18: =IFERROR( I18/H18,0) -> 0.053571429 | K18: =IFERROR(H18/G18,0) -> 0.0190541 | L18: =IF( IFERROR(IF(K17=0, 0, (K18 - K17) / K17), 0)=0," ",IFERROR(IF(K17=0, 0, (K18 - K17) / K17), 0)) -> 0.21347923 | N18: =IF($C$4="", SUMIFS('무신사 메타 광고'!$X:$X, '무신사 메타 광고'!$D:$D, $B18),SUMIFS('무신사 메타 광고'!$X:$X,'무신사 메타 광고'!I:I,$C$4,'무신사 메타 광고'!D:D,$B18)) -> 6089750 | O18: =IFERROR( N18/(N18+D18),0 ) -> 0.92630338 | R18: =IFERROR(__xludf.DUMMYFUNCTION("""COMPUTED_VALUE"""),"26년 6월 1주차") -> 26년 6월 1주차 | S18: =IF($S$4="", SUMIFS('무신사 메타 광고'!$L:$L, '무신사 메타 광고'!$C:$C, $R18),SUMIFS('무신사 메타 광고'!L:L,'무신사 메타 광고'!$I:$I,$S$4,'무신사 메타 광고'!$C:$C,$R18)) -> 426670 | T18: =IF($S$4="", SUMIFS('무신사 메타 광고'!$V:$V, '무신사 메타 광고'!$C:$C, $R18),SUMIFS('무신사 메타 광고'!$V:$V,'무신사 메타 광고'!$I:$I,$S$4,'무신사 메타 광고'!$C:$C,$R18)) -> 8898891 | U18: =IFERROR(T18/S18,0) -> 20.856613 | V18: =IF( IFERROR(IF(U17=0, 0, (U18 - U17) / U17), 0)=0," ",IFERROR(IF(U17=0, 0, (U18 - U17) / U17), 0)) -> 0.3801045 | W18: =IF($S$4="", SUMIFS('무신사 메타 광고'!$K:$K, '무신사 메타 광고'!$C:$C, $R18),SUMIFS('무신사 메타 광고'!$K:$K,'무신사 메타 광고'!$I:$I,$S$4,'무신사 메타 광고'!$C:$C,$R18)) -> 100180 | X18: =IF($S$4="", SUMIFS('무신사 메타 광고'!$N:$N, '무신사 메타 광고'!$C:$C, $R18),SUMIFS('무신사 메타 광고'!$N:$N,'무신사 메타 광고'!$I:$I,$S$4,'무신사 메타 광고'!$C:$C,$R18)) -> 2494 | Y18: =IFERROR(X18/W18,0) -> 0.024895189 | Z18: =IF( IFERROR(IF(Y17=0, 0, (Y18 - Y17) / Y17), 0)=0," ",IFERROR(IF(Y17=0, 0, (Y18 - Y17) / Y17), 0)) -> -0.025861266 | AB18: =IF($S$4="", SUMIFS('무신사 메타 광고'!$X:$X, '무신사 메타 광고'!$C:$C, $R18),SUMIFS('무신사 메타 광고'!$X:$X,'무신사 메타 광고'!$I:$I,$S$4,'무신사 메타 광고'!$C:$C,$R18)) -> 69987250 | AC18: =IFERROR( AB18/(AB18+T18),0 ) -> 0.88719323
A19: =MONTH(B19) -> 4 | B19: =IFERROR(__xludf.DUMMYFUNCTION("""COMPUTED_VALUE"""),46123) -> 46123 | C19: =IF($C$4="", SUMIFS('무신사 메타 광고'!$L:$L, '무신사 메타 광고'!$D:$D, $B19), SUMIFS('무신사 메타 광고'!$L:$L, '무신사 메타 광고'!$I:$I, $C$4, '무신사 메타 광고'!$D:$D, $B19)) -> 54355 | D19: =IF($C$4="", SUMIFS('무신사 메타 광고'!$V:$V, '무신사 메타 광고'!$D:$D, $B19), SUMIFS('무신사 메타 광고'!$V:$V,'무신사 메타 광고'!$I:$I,$C$4,'무신사 메타 광고'!$D:$D,$B19)) -> 1229400 | E19: =IFERROR(D19/C19,0) -> 22.617974 | F19: =IF( IFERROR(IF(E18=0, 0, (E19 - E18) / E18), 0)=0," ",IFERROR(IF(E18=0, 0, (E19 - E18) / E18), 0)) -> 0.21562859 | G19: =IF($C$4="", SUMIFS('무신사 메타 광고'!$K:$K, '무신사 메타 광고'!$D:$D, $B19), SUMIFS('무신사 메타 광고'!$K:$K,'무신사 메타 광고'!$I:$I,$C$4,'무신사 메타 광고'!D:D,$B19)) -> 12396 | H19: =IF($C$4="", SUMIFS('무신사 메타 광고'!$N:$N, '무신사 메타 광고'!$D:$D, $B19),SUMIFS('무신사 메타 광고'!$N:$N,'무신사 메타 광고'!$I:$I,$C$4,'무신사 메타 광고'!$D:$D,$B19)) -> 243 | I19: =IF($C$4="", SUMIFS('무신사 메타 광고'!$U:$U, '무신사 메타 광고'!$D:$D, $B19),SUMIFS('무신사 메타 광고'!$U:$U,'무신사 메타 광고'!$I:$I,$C$4,'무신사 메타 광고'!$D:$D,$B19)) -> 10 | J19: =IFERROR( I19/H19,0) -> 0.041152263 | K19: =IFERROR(H19/G19,0) -> 0.019603098 | L19: =IF( IFERROR(IF(K18=0, 0, (K19 - K18) / K18), 0)=0," ",IFERROR(IF(K18=0, 0, (K19 - K18) / K18), 0)) -> 0.028812578 | N19: =IF($C$4="", SUMIFS('무신사 메타 광고'!$X:$X, '무신사 메타 광고'!$D:$D, $B19),SUMIFS('무신사 메타 광고'!$X:$X,'무신사 메타 광고'!I:I,$C$4,'무신사 메타 광고'!D:D,$B19)) -> 8984650 | O19: =IFERROR( N19/(N19+D19),0 ) -> 0.87963638 | R19: =IFERROR(__xludf.DUMMYFUNCTION("""COMPUTED_VALUE"""),"26년 6월 2주차") -> 26년 6월 2주차 | S19: =IF($S$4="", SUMIFS('무신사 메타 광고'!$L:$L, '무신사 메타 광고'!$C:$C, $R19),SUMIFS('무신사 메타 광고'!L:L,'무신사 메타 광고'!$I:$I,$S$4,'무신사 메타 광고'!$C:$C,$R19)) -> 531792 | T19: =IF($S$4="", SUMIFS('무신사 메타 광고'!$V:$V, '무신사 메타 광고'!$C:$C, $R19),SUMIFS('무신사 메타 광고'!$V:$V,'무신사 메타 광고'!$I:$I,$S$4,'무신사 메타 광고'!$C:$C,$R19)) -> 9137200 | U19: =IFERROR(T19/S19,0) -> 17.181906 | V19: =IF( IFERROR(IF(U18=0, 0, (U19 - U18) / U18), 0)=0," ",IFERROR(IF(U18=0, 0, (U19 - U18) / U18), 0)) -> -0.17618907 | W19: =IF($S$4="", SUMIFS('무신사 메타 광고'!$K:$K, '무신사 메타 광고'!$C:$C, $R19),SUMIFS('무신사 메타 광고'!$K:$K,'무신사 메타 광고'!$I:$I,$S$4,'무신사 메타 광고'!$C:$C,$R19)) -> 98241 | X19: =IF($S$4="", SUMIFS('무신사 메타 광고'!$N:$N, '무신사 메타 광고'!$C:$C, $R19),SUMIFS('무신사 메타 광고'!$N:$N,'무신사 메타 광고'!$I:$I,$S$4,'무신사 메타 광고'!$C:$C,$R19)) -> 2630 | Y19: =IFERROR(X19/W19,0) -> 0.0267709 | Z19: =IF( IFERROR(IF(Y18=0, 0, (Y19 - Y18) / Y18), 0)=0," ",IFERROR(IF(Y18=0, 0, (Y19 - Y18) / Y18), 0)) -> 0.075344337 | AB19: =IF($S$4="", SUMIFS('무신사 메타 광고'!$X:$X, '무신사 메타 광고'!$C:$C, $R19),SUMIFS('무신사 메타 광고'!$X:$X,'무신사 메타 광고'!$I:$I,$S$4,'무신사 메타 광고'!$C:$C,$R19)) -> 55150565 | AC19: =IFERROR( AB19/(AB19+T19),0 ) -> 0.85787031
A20: =MONTH(B20) -> 4 | B20: =IFERROR(__xludf.DUMMYFUNCTION("""COMPUTED_VALUE"""),46124) -> 46124 | C20: =IF($C$4="", SUMIFS('무신사 메타 광고'!$L:$L, '무신사 메타 광고'!$D:$D, $B20), SUMIFS('무신사 메타 광고'!$L:$L, '무신사 메타 광고'!$I:$I, $C$4, '무신사 메타 광고'!$D:$D, $B20)) -> 38380 | D20: =IF($C$4="", SUMIFS('무신사 메타 광고'!$V:$V, '무신사 메타 광고'!$D:$D, $B20), SUMIFS('무신사 메타 광고'!$V:$V,'무신사 메타 광고'!$I:$I,$C$4,'무신사 메타 광고'!$D:$D,$B20)) -> 2034300 | E20: =IFERROR(D20/C20,0) -> 53.004169 | F20: =IF( IFERROR(IF(E19=0, 0, (E20 - E19) / E19), 0)=0," ",IFERROR(IF(E19=0, 0, (E20 - E19) / E19), 0)) -> 1.3434534 | G20: =IF($C$4="", SUMIFS('무신사 메타 광고'!$K:$K, '무신사 메타 광고'!$D:$D, $B20), SUMIFS('무신사 메타 광고'!$K:$K,'무신사 메타 광고'!$I:$I,$C$4,'무신사 메타 광고'!D:D,$B20)) -> 9169 | H20: =IF($C$4="", SUMIFS('무신사 메타 광고'!$N:$N, '무신사 메타 광고'!$D:$D, $B20),SUMIFS('무신사 메타 광고'!$N:$N,'무신사 메타 광고'!$I:$I,$C$4,'무신사 메타 광고'!$D:$D,$B20)) -> 152 | I20: =IF($C$4="", SUMIFS('무신사 메타 광고'!$U:$U, '무신사 메타 광고'!$D:$D, $B20),SUMIFS('무신사 메타 광고'!$U:$U,'무신사 메타 광고'!$I:$I,$C$4,'무신사 메타 광고'!$D:$D,$B20)) -> 18 | J20: =IFERROR( I20/H20,0) -> 0.11842105 | K20: =IFERROR(H20/G20,0) -> 0.016577598 | L20: =IF( IFERROR(IF(K19=0, 0, (K20 - K19) / K19), 0)=0," ",IFERROR(IF(K19=0, 0, (K20 - K19) / K19), 0)) -> -0.15433782 | N20: =IF($C$4="", SUMIFS('무신사 메타 광고'!$X:$X, '무신사 메타 광고'!$D:$D, $B20),SUMIFS('무신사 메타 광고'!$X:$X,'무신사 메타 광고'!I:I,$C$4,'무신사 메타 광고'!D:D,$B20)) -> 7352400 | O20: =IFERROR( N20/(N20+D20),0 ) -> 0.78327847 | R20: =IFERROR(__xludf.DUMMYFUNCTION("""COMPUTED_VALUE"""),"26년 6월 3주차") -> 26년 6월 3주차 | S20: =IF($S$4="", SUMIFS('무신사 메타 광고'!$L:$L, '무신사 메타 광고'!$C:$C, $R20),SUMIFS('무신사 메타 광고'!L:L,'무신사 메타 광고'!$I:$I,$S$4,'무신사 메타 광고'!$C:$C,$R20)) -> 741632 | T20: =IF($S$4="", SUMIFS('무신사 메타 광고'!$V:$V, '무신사 메타 광고'!$C:$C, $R20),SUMIFS('무신사 메타 광고'!$V:$V,'무신사 메타 광고'!$I:$I,$S$4,'무신사 메타 광고'!$C:$C,$R20)) -> 18611049 | U20: =IFERROR(T20/S20,0) -> 25.094722 | V20: =IF( IFERROR(IF(U19=0, 0, (U20 - U19) / U19), 0)=0," ",IFERROR(IF(U19=0, 0, (U20 - U19) / U19), 0)) -> 0.46053195 | W20: =IF($S$4="", SUMIFS('무신사 메타 광고'!$K:$K, '무신사 메타 광고'!$C:$C, $R20),SUMIFS('무신사 메타 광고'!$K:$K,'무신사 메타 광고'!$I:$I,$S$4,'무신사 메타 광고'!$C:$C,$R20)) -> 193002 | X20: =IF($S$4="", SUMIFS('무신사 메타 광고'!$N:$N, '무신사 메타 광고'!$C:$C, $R20),SUMIFS('무신사 메타 광고'!$N:$N,'무신사 메타 광고'!$I:$I,$S$4,'무신사 메타 광고'!$C:$C,$R20)) -> 5793 | Y20: =IFERROR(X20/W20,0) -> 0.030015233 | Z20: =IF( IFERROR(IF(Y19=0, 0, (Y20 - Y19) / Y19), 0)=0," ",IFERROR(IF(Y19=0, 0, (Y20 - Y19) / Y19), 0)) -> 0.12118879 | AB20: =IF($S$4="", SUMIFS('무신사 메타 광고'!$X:$X, '무신사 메타 광고'!$C:$C, $R20),SUMIFS('무신사 메타 광고'!$X:$X,'무신사 메타 광고'!$I:$I,$S$4,'무신사 메타 광고'!$C:$C,$R20)) -> 93739943 | AC20: =IFERROR( AB20/(AB20+T20),0 ) -> 0.83434905
A21: =MONTH(B21) -> 4 | B21: =IFERROR(__xludf.DUMMYFUNCTION("""COMPUTED_VALUE"""),46125) -> 46125 | C21: =IF($C$4="", SUMIFS('무신사 메타 광고'!$L:$L, '무신사 메타 광고'!$D:$D, $B21), SUMIFS('무신사 메타 광고'!$L:$L, '무신사 메타 광고'!$I:$I, $C$4, '무신사 메타 광고'!$D:$D, $B21)) -> 35389 | D21: =IF($C$4="", SUMIFS('무신사 메타 광고'!$V:$V, '무신사 메타 광고'!$D:$D, $B21), SUMIFS('무신사 메타 광고'!$V:$V,'무신사 메타 광고'!$I:$I,$C$4,'무신사 메타 광고'!$D:$D,$B21)) -> 643500 | E21: =IFERROR(D21/C21,0) -> 18.183616 | F21: =IF( IFERROR(IF(E20=0, 0, (E21 - E20) / E20), 0)=0," ",IFERROR(IF(E20=0, 0, (E21 - E20) / E20), 0)) -> -0.65693988 | G21: =IF($C$4="", SUMIFS('무신사 메타 광고'!$K:$K, '무신사 메타 광고'!$D:$D, $B21), SUMIFS('무신사 메타 광고'!$K:$K,'무신사 메타 광고'!$I:$I,$C$4,'무신사 메타 광고'!D:D,$B21)) -> 8498 | H21: =IF($C$4="", SUMIFS('무신사 메타 광고'!$N:$N, '무신사 메타 광고'!$D:$D, $B21),SUMIFS('무신사 메타 광고'!$N:$N,'무신사 메타 광고'!$I:$I,$C$4,'무신사 메타 광고'!$D:$D,$B21)) -> 112 | I21: =IF($C$4="", SUMIFS('무신사 메타 광고'!$U:$U, '무신사 메타 광고'!$D:$D, $B21),SUMIFS('무신사 메타 광고'!$U:$U,'무신사 메타 광고'!$I:$I,$C$4,'무신사 메타 광고'!$D:$D,$B21)) -> 5 | J21: =IFERROR( I21/H21,0) -> 0.044642857 | K21: =IFERROR(H21/G21,0) -> 0.013179572 | L21: =IF( IFERROR(IF(K20=0, 0, (K21 - K20) / K20), 0)=0," ",IFERROR(IF(K20=0, 0, (K21 - K20) / K20), 0)) -> -0.20497702 | N21: =IF($C$4="", SUMIFS('무신사 메타 광고'!$X:$X, '무신사 메타 광고'!$D:$D, $B21),SUMIFS('무신사 메타 광고'!$X:$X,'무신사 메타 광고'!I:I,$C$4,'무신사 메타 광고'!D:D,$B21)) -> 5352200 | O21: =IFERROR( N21/(N21+D21),0 ) -> 0.89267308 | R21: =IFERROR(__xludf.DUMMYFUNCTION("""COMPUTED_VALUE"""),"26년 6월 4주차") -> 26년 6월 4주차 | S21: =IF($S$4="", SUMIFS('무신사 메타 광고'!$L:$L, '무신사 메타 광고'!$C:$C, $R21),SUMIFS('무신사 메타 광고'!L:L,'무신사 메타 광고'!$I:$I,$S$4,'무신사 메타 광고'!$C:$C,$R21)) -> 305818 | T21: =IF($S$4="", SUMIFS('무신사 메타 광고'!$V:$V, '무신사 메타 광고'!$C:$C, $R21),SUMIFS('무신사 메타 광고'!$V:$V,'무신사 메타 광고'!$I:$I,$S$4,'무신사 메타 광고'!$C:$C,$R21)) -> 7399313 | U21: =IFERROR(T21/S21,0) -> 24.195152 | V21: =IF( IFERROR(IF(U20=0, 0, (U21 - U20) / U20), 0)=0," ",IFERROR(IF(U20=0, 0, (U21 - U20) / U20), 0)) -> -0.035846986 | W21: =IF($S$4="", SUMIFS('무신사 메타 광고'!$K:$K, '무신사 메타 광고'!$C:$C, $R21),SUMIFS('무신사 메타 광고'!$K:$K,'무신사 메타 광고'!$I:$I,$S$4,'무신사 메타 광고'!$C:$C,$R21)) -> 84161 | X21: =IF($S$4="", SUMIFS('무신사 메타 광고'!$N:$N, '무신사 메타 광고'!$C:$C, $R21),SUMIFS('무신사 메타 광고'!$N:$N,'무신사 메타 광고'!$I:$I,$S$4,'무신사 메타 광고'!$C:$C,$R21)) -> 2232 | Y21: =IFERROR(X21/W21,0) -> 0.026520597 | Z21: =IF( IFERROR(IF(Y20=0, 0, (Y21 - Y20) / Y20), 0)=0," ",IFERROR(IF(Y20=0, 0, (Y21 - Y20) / Y20), 0)) -> -0.11642873 | AB21: =IF($S$4="", SUMIFS('무신사 메타 광고'!$X:$X, '무신사 메타 광고'!$C:$C, $R21),SUMIFS('무신사 메타 광고'!$X:$X,'무신사 메타 광고'!$I:$I,$S$4,'무신사 메타 광고'!$C:$C,$R21)) -> 28775428 | AC21: =IFERROR( AB21/(AB21+T21),0 ) -> 0.79545637
A22: =MONTH(B22) -> 4 | B22: =IFERROR(__xludf.DUMMYFUNCTION("""COMPUTED_VALUE"""),46126) -> 46126 | C22: =IF($C$4="", SUMIFS('무신사 메타 광고'!$L:$L, '무신사 메타 광고'!$D:$D, $B22), SUMIFS('무신사 메타 광고'!$L:$L, '무신사 메타 광고'!$I:$I, $C$4, '무신사 메타 광고'!$D:$D, $B22)) -> 44004 | D22: =IF($C$4="", SUMIFS('무신사 메타 광고'!$V:$V, '무신사 메타 광고'!$D:$D, $B22), SUMIFS('무신사 메타 광고'!$V:$V,'무신사 메타 광고'!$I:$I,$C$4,'무신사 메타 광고'!$D:$D,$B22)) -> 811050 | E22: =IFERROR(D22/C22,0) -> 18.431279 | F22: =IF( IFERROR(IF(E21=0, 0, (E22 - E21) / E21), 0)=0," ",IFERROR(IF(E21=0, 0, (E22 - E21) / E21), 0)) -> 0.013620096 | G22: =IF($C$4="", SUMIFS('무신사 메타 광고'!$K:$K, '무신사 메타 광고'!$D:$D, $B22), SUMIFS('무신사 메타 광고'!$K:$K,'무신사 메타 광고'!$I:$I,$C$4,'무신사 메타 광고'!D:D,$B22)) -> 9622 | H22: =IF($C$4="", SUMIFS('무신사 메타 광고'!$N:$N, '무신사 메타 광고'!$D:$D, $B22),SUMIFS('무신사 메타 광고'!$N:$N,'무신사 메타 광고'!$I:$I,$C$4,'무신사 메타 광고'!$D:$D,$B22)) -> 146 | I22: =IF($C$4="", SUMIFS('무신사 메타 광고'!$U:$U, '무신사 메타 광고'!$D:$D, $B22),SUMIFS('무신사 메타 광고'!$U:$U,'무신사 메타 광고'!$I:$I,$C$4,'무신사 메타 광고'!$D:$D,$B22)) -> 7 | J22: =IFERROR( I22/H22,0) -> 0.047945205 | K22: =IFERROR(H22/G22,0) -> 0.015173561 | L22: =IF( IFERROR(IF(K21=0, 0, (K22 - K21) / K21), 0)=0," ",IFERROR(IF(K21=0, 0, (K22 - K21) / K21), 0)) -> 0.15129391 | N22: =IF($C$4="", SUMIFS('무신사 메타 광고'!$X:$X, '무신사 메타 광고'!$D:$D, $B22),SUMIFS('무신사 메타 광고'!$X:$X,'무신사 메타 광고'!I:I,$C$4,'무신사 메타 광고'!D:D,$B22)) -> 8998350 | O22: =IFERROR( N22/(N22+D22),0 ) -> 0.9173191 | R22: =IFERROR(__xludf.DUMMYFUNCTION("""COMPUTED_VALUE"""),"99년 12월 1주차") -> 99년 12월 1주차 | S22: =IF($S$4="", SUMIFS('무신사 메타 광고'!$L:$L, '무신사 메타 광고'!$C:$C, $R22),SUMIFS('무신사 메타 광고'!L:L,'무신사 메타 광고'!$I:$I,$S$4,'무신사 메타 광고'!$C:$C,$R22)) -> 0 | T22: =IF($S$4="", SUMIFS('무신사 메타 광고'!$V:$V, '무신사 메타 광고'!$C:$C, $R22),SUMIFS('무신사 메타 광고'!$V:$V,'무신사 메타 광고'!$I:$I,$S$4,'무신사 메타 광고'!$C:$C,$R22)) -> 0 | U22: =IFERROR(T22/S22,0) -> 0 | V22: =IF( IFERROR(IF(U21=0, 0, (U22 - U21) / U21), 0)=0," ",IFERROR(IF(U21=0, 0, (U22 - U21) / U21), 0)) -> -1 | W22: =IF($S$4="", SUMIFS('무신사 메타 광고'!$K:$K, '무신사 메타 광고'!$C:$C, $R22),SUMIFS('무신사 메타 광고'!$K:$K,'무신사 메타 광고'!$I:$I,$S$4,'무신사 메타 광고'!$C:$C,$R22)) -> 0 | X22: =IF($S$4="", SUMIFS('무신사 메타 광고'!$N:$N, '무신사 메타 광고'!$C:$C, $R22),SUMIFS('무신사 메타 광고'!$N:$N,'무신사 메타 광고'!$I:$I,$S$4,'무신사 메타 광고'!$C:$C,$R22)) -> 0 | Y22: =IFERROR(X22/W22,0) -> 0 | Z22: =IF( IFERROR(IF(Y21=0, 0, (Y22 - Y21) / Y21), 0)=0," ",IFERROR(IF(Y21=0, 0, (Y22 - Y21) / Y21), 0)) -> -1 | AB22: =IF($S$4="", SUMIFS('무신사 메타 광고'!$X:$X, '무신사 메타 광고'!$C:$C, $R22),SUMIFS('무신사 메타 광고'!$X:$X,'무신사 메타 광고'!$I:$I,$S$4,'무신사 메타 광고'!$C:$C,$R22)) -> 0 | AC22: =IFERROR( AB22/(AB22+T22),0 ) -> 0
A23: =MONTH(B23) -> 4 | B23: =IFERROR(__xludf.DUMMYFUNCTION("""COMPUTED_VALUE"""),46127) -> 46127 | C23: =IF($C$4="", SUMIFS('무신사 메타 광고'!$L:$L, '무신사 메타 광고'!$D:$D, $B23), SUMIFS('무신사 메타 광고'!$L:$L, '무신사 메타 광고'!$I:$I, $C$4, '무신사 메타 광고'!$D:$D, $B23)) -> 42299 | D23: =IF($C$4="", SUMIFS('무신사 메타 광고'!$V:$V, '무신사 메타 광고'!$D:$D, $B23), SUMIFS('무신사 메타 광고'!$V:$V,'무신사 메타 광고'!$I:$I,$C$4,'무신사 메타 광고'!$D:$D,$B23)) -> 1743300 | E23: =IFERROR(D23/C23,0) -> 41.21374 | F23: =IF( IFERROR(IF(E22=0, 0, (E23 - E22) / E22), 0)=0," ",IFERROR(IF(E22=0, 0, (E23 - E22) / E22), 0)) -> 1.236076 | G23: =IF($C$4="", SUMIFS('무신사 메타 광고'!$K:$K, '무신사 메타 광고'!$D:$D, $B23), SUMIFS('무신사 메타 광고'!$K:$K,'무신사 메타 광고'!$I:$I,$C$4,'무신사 메타 광고'!D:D,$B23)) -> 9481 | H23: =IF($C$4="", SUMIFS('무신사 메타 광고'!$N:$N, '무신사 메타 광고'!$D:$D, $B23),SUMIFS('무신사 메타 광고'!$N:$N,'무신사 메타 광고'!$I:$I,$C$4,'무신사 메타 광고'!$D:$D,$B23)) -> 161 | I23: =IF($C$4="", SUMIFS('무신사 메타 광고'!$U:$U, '무신사 메타 광고'!$D:$D, $B23),SUMIFS('무신사 메타 광고'!$U:$U,'무신사 메타 광고'!$I:$I,$C$4,'무신사 메타 광고'!$D:$D,$B23)) -> 15 | J23: =IFERROR( I23/H23,0) -> 0.093167702 | K23: =IFERROR(H23/G23,0) -> 0.016981331 | L23: =IF( IFERROR(IF(K22=0, 0, (K23 - K22) / K22), 0)=0," ",IFERROR(IF(K22=0, 0, (K23 - K22) / K22), 0)) -> 0.1191395 | N23: =IF($C$4="", SUMIFS('무신사 메타 광고'!$X:$X, '무신사 메타 광고'!$D:$D, $B23),SUMIFS('무신사 메타 광고'!$X:$X,'무신사 메타 광고'!I:I,$C$4,'무신사 메타 광고'!D:D,$B23)) -> 13298786 | O23: =IFERROR( N23/(N23+D23),0 ) -> 0.88410517 | S23: =IF($S$4="", SUMIFS('무신사 메타 광고'!$L:$L, '무신사 메타 광고'!$C:$C, $R23),SUMIFS('무신사 메타 광고'!L:L,'무신사 메타 광고'!$I:$I,$S$4,'무신사 메타 광고'!$C:$C,$R23)) -> 0 | T23: =IF($S$4="", SUMIFS('무신사 메타 광고'!$V:$V, '무신사 메타 광고'!$C:$C, $R23),SUMIFS('무신사 메타 광고'!$V:$V,'무신사 메타 광고'!$I:$I,$S$4,'무신사 메타 광고'!$C:$C,$R23)) -> 0 | U23: =IFERROR(T23/S23,0) -> 0 | V23: =IF( IFERROR(IF(U22=0, 0, (U23 - U22) / U22), 0)=0," ",IFERROR(IF(U22=0, 0, (U23 - U22) / U22), 0)) | W23: =IF($S$4="", SUMIFS('무신사 메타 광고'!$K:$K, '무신사 메타 광고'!$C:$C, $R23),SUMIFS('무신사 메타 광고'!$K:$K,'무신사 메타 광고'!$I:$I,$S$4,'무신사 메타 광고'!$C:$C,$R23)) -> 0 | X23: =IF($S$4="", SUMIFS('무신사 메타 광고'!$N:$N, '무신사 메타 광고'!$C:$C, $R23),SUMIFS('무신사 메타 광고'!$N:$N,'무신사 메타 광고'!$I:$I,$S$4,'무신사 메타 광고'!$C:$C,$R23)) -> 0 | Y23: =IFERROR(X23/W23,0) -> 0 | Z23: =IF( IFERROR(IF(Y22=0, 0, (Y23 - Y22) / Y22), 0)=0," ",IFERROR(IF(Y22=0, 0, (Y23 - Y22) / Y22), 0)) | AB23: =IF($S$4="", SUMIFS('무신사 메타 광고'!$X:$X, '무신사 메타 광고'!$C:$C, $R23),SUMIFS('무신사 메타 광고'!$X:$X,'무신사 메타 광고'!$I:$I,$S$4,'무신사 메타 광고'!$C:$C,$R23)) -> 0 | AC23: =IFERROR( AB23/(AB23+T23),0 ) -> 0
A24: =MONTH(B24) -> 4 | B24: =IFERROR(__xludf.DUMMYFUNCTION("""COMPUTED_VALUE"""),46128) -> 46128 | C24: =IF($C$4="", SUMIFS('무신사 메타 광고'!$L:$L, '무신사 메타 광고'!$D:$D, $B24), SUMIFS('무신사 메타 광고'!$L:$L, '무신사 메타 광고'!$I:$I, $C$4, '무신사 메타 광고'!$D:$D, $B24)) -> 54815 | D24: =IF($C$4="", SUMIFS('무신사 메타 광고'!$V:$V, '무신사 메타 광고'!$D:$D, $B24), SUMIFS('무신사 메타 광고'!$V:$V,'무신사 메타 광고'!$I:$I,$C$4,'무신사 메타 광고'!$D:$D,$B24)) -> 1819250 | E24: =IFERROR(D24/C24,0) -> 33.188908 | F24: =IF( IFERROR(IF(E23=0, 0, (E24 - E23) / E23), 0)=0," ",IFERROR(IF(E23=0, 0, (E24 - E23) / E23), 0)) -> -0.19471254 | G24: =IF($C$4="", SUMIFS('무신사 메타 광고'!$K:$K, '무신사 메타 광고'!$D:$D, $B24), SUMIFS('무신사 메타 광고'!$K:$K,'무신사 메타 광고'!$I:$I,$C$4,'무신사 메타 광고'!D:D,$B24)) -> 14232 | I24: =IF($C$4="", SUMIFS('무신사 메타 광고'!$U:$U, '무신사 메타 광고'!$D:$D, $B24),SUMIFS('무신사 메타 광고'!$U:$U,'무신사 메타 광고'!$I:$I,$C$4,'무신사 메타 광고'!$D:$D,$B24)) -> 16 | J24: =IFERROR( I24/H24,0) -> 0 | K24: =IFERROR(H24/G24,0) -> 0 | L24: =IF( IFERROR(IF(K23=0, 0, (K24 - K23) / K23), 0)=0," ",IFERROR(IF(K23=0, 0, (K24 - K23) / K23), 0)) -> -1 | N24: =IF($C$4="", SUMIFS('무신사 메타 광고'!$X:$X, '무신사 메타 광고'!$D:$D, $B24),SUMIFS('무신사 메타 광고'!$X:$X,'무신사 메타 광고'!I:I,$C$4,'무신사 메타 광고'!D:D,$B24)) -> 13187275 | O24: =IFERROR( N24/(N24+D24),0 ) -> 0.8787694 | S24: =IF($S$4="", SUMIFS('무신사 메타 광고'!$L:$L, '무신사 메타 광고'!$C:$C, $R24),SUMIFS('무신사 메타 광고'!L:L,'무신사 메타 광고'!$I:$I,$S$4,'무신사 메타 광고'!$C:$C,$R24)) -> 0 | T24: =IF($S$4="", SUMIFS('무신사 메타 광고'!$V:$V, '무신사 메타 광고'!$C:$C, $R24),SUMIFS('무신사 메타 광고'!$V:$V,'무신사 메타 광고'!$I:$I,$S$4,'무신사 메타 광고'!$C:$C,$R24)) -> 0 | U24: =IFERROR(T24/S24,0) -> 0 | V24: =IF( IFERROR(IF(U23=0, 0, (U24 - U23) / U23), 0)=0," ",IFERROR(IF(U23=0, 0, (U24 - U23) / U23), 0)) | W24: =IF($S$4="", SUMIFS('무신사 메타 광고'!$K:$K, '무신사 메타 광고'!$C:$C, $R24),SUMIFS('무신사 메타 광고'!$K:$K,'무신사 메타 광고'!$I:$I,$S$4,'무신사 메타 광고'!$C:$C,$R24)) -> 0 | X24: =IF($S$4="", SUMIFS('무신사 메타 광고'!$N:$N, '무신사 메타 광고'!$C:$C, $R24),SUMIFS('무신사 메타 광고'!$N:$N,'무신사 메타 광고'!$I:$I,$S$4,'무신사 메타 광고'!$C:$C,$R24)) -> 0 | Y24: =IFERROR(X24/W24,0) -> 0 | Z24: =IF( IFERROR(IF(Y23=0, 0, (Y24 - Y23) / Y23), 0)=0," ",IFERROR(IF(Y23=0, 0, (Y24 - Y23) / Y23), 0)) | AB24: =IF($S$4="", SUMIFS('무신사 메타 광고'!$X:$X, '무신사 메타 광고'!$C:$C, $R24),SUMIFS('무신사 메타 광고'!$X:$X,'무신사 메타 광고'!$I:$I,$S$4,'무신사 메타 광고'!$C:$C,$R24)) -> 0 | AC24: =IFERROR( AB24/(AB24+T24),0 ) -> 0
A25: =MONTH(B25) -> 4 | B25: =IFERROR(__xludf.DUMMYFUNCTION("""COMPUTED_VALUE"""),46129) -> 46129 | C25: =IF($C$4="", SUMIFS('무신사 메타 광고'!$L:$L, '무신사 메타 광고'!$D:$D, $B25), SUMIFS('무신사 메타 광고'!$L:$L, '무신사 메타 광고'!$I:$I, $C$4, '무신사 메타 광고'!$D:$D, $B25)) -> 56520 | D25: =IF($C$4="", SUMIFS('무신사 메타 광고'!$V:$V, '무신사 메타 광고'!$D:$D, $B25), SUMIFS('무신사 메타 광고'!$V:$V,'무신사 메타 광고'!$I:$I,$C$4,'무신사 메타 광고'!$D:$D,$B25)) -> 1141350 | E25: =IFERROR(D25/C25,0) -> 20.193737 | F25: =IF( IFERROR(IF(E24=0, 0, (E25 - E24) / E24), 0)=0," ",IFERROR(IF(E24=0, 0, (E25 - E24) / E24), 0)) -> -0.39155164 | G25: =IF($C$4="", SUMIFS('무신사 메타 광고'!$K:$K, '무신사 메타 광고'!$D:$D, $B25), SUMIFS('무신사 메타 광고'!$K:$K,'무신사 메타 광고'!$I:$I,$C$4,'무신사 메타 광고'!D:D,$B25)) -> 16004 | H25: =IF($C$4="", SUMIFS('무신사 메타 광고'!$N:$N, '무신사 메타 광고'!$D:$D, $B25),SUMIFS('무신사 메타 광고'!$N:$N,'무신사 메타 광고'!$I:$I,$C$4,'무신사 메타 광고'!$D:$D,$B25)) -> 354 | I25: =IF($C$4="", SUMIFS('무신사 메타 광고'!$U:$U, '무신사 메타 광고'!$D:$D, $B25),SUMIFS('무신사 메타 광고'!$U:$U,'무신사 메타 광고'!$I:$I,$C$4,'무신사 메타 광고'!$D:$D,$B25)) -> 10 | J25: =IFERROR( I25/H25,0) -> 0.028248588 | K25: =IFERROR(H25/G25,0) -> 0.02211947 | L25: =IF( IFERROR(IF(K24=0, 0, (K25 - K24) / K24), 0)=0," ",IFERROR(IF(K24=0, 0, (K25 - K24) / K24), 0)) | N25: =IF($C$4="", SUMIFS('무신사 메타 광고'!$X:$X, '무신사 메타 광고'!$D:$D, $B25),SUMIFS('무신사 메타 광고'!$X:$X,'무신사 메타 광고'!I:I,$C$4,'무신사 메타 광고'!D:D,$B25)) -> 14729266 | O25: =IFERROR( N25/(N25+D25),0 ) -> 0.92808408 | S25: =IF($S$4="", SUMIFS('무신사 메타 광고'!$L:$L, '무신사 메타 광고'!$C:$C, $R25),SUMIFS('무신사 메타 광고'!L:L,'무신사 메타 광고'!$I:$I,$S$4,'무신사 메타 광고'!$C:$C,$R25)) -> 0 | T25: =IF($S$4="", SUMIFS('무신사 메타 광고'!$V:$V, '무신사 메타 광고'!$C:$C, $R25),SUMIFS('무신사 메타 광고'!$V:$V,'무신사 메타 광고'!$I:$I,$S$4,'무신사 메타 광고'!$C:$C,$R25)) -> 0 | U25: =IFERROR(T25/S25,0) -> 0 | V25: =IF( IFERROR(IF(U24=0, 0, (U25 - U24) / U24), 0)=0," ",IFERROR(IF(U24=0, 0, (U25 - U24) / U24), 0)) | W25: =IF($S$4="", SUMIFS('무신사 메타 광고'!$K:$K, '무신사 메타 광고'!$C:$C, $R25),SUMIFS('무신사 메타 광고'!$K:$K,'무신사 메타 광고'!$I:$I,$S$4,'무신사 메타 광고'!$C:$C,$R25)) -> 0 | X25: =IF($S$4="", SUMIFS('무신사 메타 광고'!$N:$N, '무신사 메타 광고'!$C:$C, $R25),SUMIFS('무신사 메타 광고'!$N:$N,'무신사 메타 광고'!$I:$I,$S$4,'무신사 메타 광고'!$C:$C,$R25)) -> 0 | Y25: =IFERROR(X25/W25,0) -> 0 | Z25: =IF( IFERROR(IF(Y24=0, 0, (Y25 - Y24) / Y24), 0)=0," ",IFERROR(IF(Y24=0, 0, (Y25 - Y24) / Y24), 0)) | AB25: =IF($S$4="", SUMIFS('무신사 메타 광고'!$X:$X, '무신사 메타 광고'!$C:$C, $R25),SUMIFS('무신사 메타 광고'!$X:$X,'무신사 메타 광고'!$I:$I,$S$4,'무신사 메타 광고'!$C:$C,$R25)) -> 0 | AC25: =IFERROR( AB25/(AB25+T25),0 ) -> 0
A26: =MONTH(B26) -> 4 | B26: =IFERROR(__xludf.DUMMYFUNCTION("""COMPUTED_VALUE"""),46130) -> 46130 | C26: =IF($C$4="", SUMIFS('무신사 메타 광고'!$L:$L, '무신사 메타 광고'!$D:$D, $B26), SUMIFS('무신사 메타 광고'!$L:$L, '무신사 메타 광고'!$I:$I, $C$4, '무신사 메타 광고'!$D:$D, $B26)) -> 53146 | D26: =IF($C$4="", SUMIFS('무신사 메타 광고'!$V:$V, '무신사 메타 광고'!$D:$D, $B26), SUMIFS('무신사 메타 광고'!$V:$V,'무신사 메타 광고'!$I:$I,$C$4,'무신사 메타 광고'!$D:$D,$B26)) -> 445000 | E26: =IFERROR(D26/C26,0) -> 8.3731607 | F26: =IF( IFERROR(IF(E25=0, 0, (E26 - E25) / E25), 0)=0," ",IFERROR(IF(E25=0, 0, (E26 - E25) / E25), 0)) -> -0.58535853 | G26: =IF($C$4="", SUMIFS('무신사 메타 광고'!$K:$K, '무신사 메타 광고'!$D:$D, $B26), SUMIFS('무신사 메타 광고'!$K:$K,'무신사 메타 광고'!$I:$I,$C$4,'무신사 메타 광고'!D:D,$B26)) -> 16356 | H26: =IF($C$4="", SUMIFS('무신사 메타 광고'!$N:$N, '무신사 메타 광고'!$D:$D, $B26),SUMIFS('무신사 메타 광고'!$N:$N,'무신사 메타 광고'!$I:$I,$C$4,'무신사 메타 광고'!$D:$D,$B26)) -> 453 | I26: =IF($C$4="", SUMIFS('무신사 메타 광고'!$U:$U, '무신사 메타 광고'!$D:$D, $B26),SUMIFS('무신사 메타 광고'!$U:$U,'무신사 메타 광고'!$I:$I,$C$4,'무신사 메타 광고'!$D:$D,$B26)) -> 6 | J26: =IFERROR( I26/H26,0) -> 0.013245033 | K26: =IFERROR(H26/G26,0) -> 0.027696258 | L26: =IF( IFERROR(IF(K25=0, 0, (K26 - K25) / K25), 0)=0," ",IFERROR(IF(K25=0, 0, (K26 - K25) / K25), 0)) -> 0.25212123 | N26: =IF($C$4="", SUMIFS('무신사 메타 광고'!$X:$X, '무신사 메타 광고'!$D:$D, $B26),SUMIFS('무신사 메타 광고'!$X:$X,'무신사 메타 광고'!I:I,$C$4,'무신사 메타 광고'!D:D,$B26)) -> 16377000 | O26: =IFERROR( N26/(N26+D26),0 ) -> 0.97354655 | S26: =IF($S$4="", SUMIFS('무신사 메타 광고'!$L:$L, '무신사 메타 광고'!$C:$C, $R26),SUMIFS('무신사 메타 광고'!L:L,'무신사 메타 광고'!$I:$I,$S$4,'무신사 메타 광고'!$C:$C,$R26)) -> 0 | T26: =IF($S$4="", SUMIFS('무신사 메타 광고'!$V:$V, '무신사 메타 광고'!$C:$C, $R26),SUMIFS('무신사 메타 광고'!$V:$V,'무신사 메타 광고'!$I:$I,$S$4,'무신사 메타 광고'!$C:$C,$R26)) -> 0 | U26: =IFERROR(T26/S26,0) -> 0 | V26: =IF( IFERROR(IF(U25=0, 0, (U26 - U25) / U25), 0)=0," ",IFERROR(IF(U25=0, 0, (U26 - U25) / U25), 0)) | W26: =IF($S$4="", SUMIFS('무신사 메타 광고'!$K:$K, '무신사 메타 광고'!$C:$C, $R26),SUMIFS('무신사 메타 광고'!$K:$K,'무신사 메타 광고'!$I:$I,$S$4,'무신사 메타 광고'!$C:$C,$R26)) -> 0 | X26: =IF($S$4="", SUMIFS('무신사 메타 광고'!$N:$N, '무신사 메타 광고'!$C:$C, $R26),SUMIFS('무신사 메타 광고'!$N:$N,'무신사 메타 광고'!$I:$I,$S$4,'무신사 메타 광고'!$C:$C,$R26)) -> 0 | Y26: =IFERROR(X26/W26,0) -> 0 | Z26: =IF( IFERROR(IF(Y25=0, 0, (Y26 - Y25) / Y25), 0)=0," ",IFERROR(IF(Y25=0, 0, (Y26 - Y25) / Y25), 0)) | AB26: =IF($S$4="", SUMIFS('무신사 메타 광고'!$X:$X, '무신사 메타 광고'!$C:$C, $R26),SUMIFS('무신사 메타 광고'!$X:$X,'무신사 메타 광고'!$I:$I,$S$4,'무신사 메타 광고'!$C:$C,$R26)) -> 0 | AC26: =IFERROR( AB26/(AB26+T26),0 ) -> 0
A27: =MONTH(B27) -> 4 | B27: =IFERROR(__xludf.DUMMYFUNCTION("""COMPUTED_VALUE"""),46131) -> 46131 | C27: =IF($C$4="", SUMIFS('무신사 메타 광고'!$L:$L, '무신사 메타 광고'!$D:$D, $B27), SUMIFS('무신사 메타 광고'!$L:$L, '무신사 메타 광고'!$I:$I, $C$4, '무신사 메타 광고'!$D:$D, $B27)) -> 55963 | D27: =IF($C$4="", SUMIFS('무신사 메타 광고'!$V:$V, '무신사 메타 광고'!$D:$D, $B27), SUMIFS('무신사 메타 광고'!$V:$V,'무신사 메타 광고'!$I:$I,$C$4,'무신사 메타 광고'!$D:$D,$B27)) -> 2436750 | E27: =IFERROR(D27/C27,0) -> 43.542162 | F27: =IF( IFERROR(IF(E26=0, 0, (E27 - E26) / E26), 0)=0," ",IFERROR(IF(E26=0, 0, (E27 - E26) / E26), 0)) -> 4.2002061 | G27: =IF($C$4="", SUMIFS('무신사 메타 광고'!$K:$K, '무신사 메타 광고'!$D:$D, $B27), SUMIFS('무신사 메타 광고'!$K:$K,'무신사 메타 광고'!$I:$I,$C$4,'무신사 메타 광고'!D:D,$B27)) -> 17882 | H27: =IF($C$4="", SUMIFS('무신사 메타 광고'!$N:$N, '무신사 메타 광고'!$D:$D, $B27),SUMIFS('무신사 메타 광고'!$N:$N,'무신사 메타 광고'!$I:$I,$C$4,'무신사 메타 광고'!$D:$D,$B27)) -> 432 | I27: =IF($C$4="", SUMIFS('무신사 메타 광고'!$U:$U, '무신사 메타 광고'!$D:$D, $B27),SUMIFS('무신사 메타 광고'!$U:$U,'무신사 메타 광고'!$I:$I,$C$4,'무신사 메타 광고'!$D:$D,$B27)) -> 20 | J27: =IFERROR( I27/H27,0) -> 0.046296296 | K27: =IFERROR(H27/G27,0) -> 0.024158372 | L27: =IF( IFERROR(IF(K26=0, 0, (K27 - K26) / K26), 0)=0," ",IFERROR(IF(K26=0, 0, (K27 - K26) / K26), 0)) -> -0.1277388 | N27: =IF($C$4="", SUMIFS('무신사 메타 광고'!$X:$X, '무신사 메타 광고'!$D:$D, $B27),SUMIFS('무신사 메타 광고'!$X:$X,'무신사 메타 광고'!I:I,$C$4,'무신사 메타 광고'!D:D,$B27)) -> 19287710 | O27: =IFERROR( N27/(N27+D27),0 ) -> 0.88783381 | S27: =IF($S$4="", SUMIFS('무신사 메타 광고'!$L:$L, '무신사 메타 광고'!$C:$C, $R27),SUMIFS('무신사 메타 광고'!L:L,'무신사 메타 광고'!$I:$I,$S$4,'무신사 메타 광고'!$C:$C,$R27)) -> 0 | T27: =IF($S$4="", SUMIFS('무신사 메타 광고'!$V:$V, '무신사 메타 광고'!$C:$C, $R27),SUMIFS('무신사 메타 광고'!$V:$V,'무신사 메타 광고'!$I:$I,$S$4,'무신사 메타 광고'!$C:$C,$R27)) -> 0 | U27: =IFERROR(T27/S27,0) -> 0 | V27: =IF( IFERROR(IF(U26=0, 0, (U27 - U26) / U26), 0)=0," ",IFERROR(IF(U26=0, 0, (U27 - U26) / U26), 0)) | W27: =IF($S$4="", SUMIFS('무신사 메타 광고'!$K:$K, '무신사 메타 광고'!$C:$C, $R27),SUMIFS('무신사 메타 광고'!$K:$K,'무신사 메타 광고'!$I:$I,$S$4,'무신사 메타 광고'!$C:$C,$R27)) -> 0 | X27: =IF($S$4="", SUMIFS('무신사 메타 광고'!$N:$N, '무신사 메타 광고'!$C:$C, $R27),SUMIFS('무신사 메타 광고'!$N:$N,'무신사 메타 광고'!$I:$I,$S$4,'무신사 메타 광고'!$C:$C,$R27)) -> 0 | Y27: =IFERROR(X27/W27,0) -> 0 | Z27: =IF( IFERROR(IF(Y26=0, 0, (Y27 - Y26) / Y26), 0)=0," ",IFERROR(IF(Y26=0, 0, (Y27 - Y26) / Y26), 0)) | AB27: =IF($S$4="", SUMIFS('무신사 메타 광고'!$X:$X, '무신사 메타 광고'!$C:$C, $R27),SUMIFS('무신사 메타 광고'!$X:$X,'무신사 메타 광고'!$I:$I,$S$4,'무신사 메타 광고'!$C:$C,$R27)) -> 0 | AC27: =IFERROR( AB27/(AB27+T27),0 ) -> 0
A28: =MONTH(B28) -> 4 | B28: =IFERROR(__xludf.DUMMYFUNCTION("""COMPUTED_VALUE"""),46132) -> 46132 | C28: =IF($C$4="", SUMIFS('무신사 메타 광고'!$L:$L, '무신사 메타 광고'!$D:$D, $B28), SUMIFS('무신사 메타 광고'!$L:$L, '무신사 메타 광고'!$I:$I, $C$4, '무신사 메타 광고'!$D:$D, $B28)) -> 60554 | D28: =IF($C$4="", SUMIFS('무신사 메타 광고'!$V:$V, '무신사 메타 광고'!$D:$D, $B28), SUMIFS('무신사 메타 광고'!$V:$V,'무신사 메타 광고'!$I:$I,$C$4,'무신사 메타 광고'!$D:$D,$B28)) -> 1186350 | E28: =IFERROR(D28/C28,0) -> 19.591604 | F28: =IF( IFERROR(IF(E27=0, 0, (E28 - E27) / E27), 0)=0," ",IFERROR(IF(E27=0, 0, (E28 - E27) / E27), 0)) -> -0.5500544 | G28: =IF($C$4="", SUMIFS('무신사 메타 광고'!$K:$K, '무신사 메타 광고'!$D:$D, $B28), SUMIFS('무신사 메타 광고'!$K:$K,'무신사 메타 광고'!$I:$I,$C$4,'무신사 메타 광고'!D:D,$B28)) -> 18373 | H28: =IF($C$4="", SUMIFS('무신사 메타 광고'!$N:$N, '무신사 메타 광고'!$D:$D, $B28),SUMIFS('무신사 메타 광고'!$N:$N,'무신사 메타 광고'!$I:$I,$C$4,'무신사 메타 광고'!$D:$D,$B28)) -> 402 | I28: =IF($C$4="", SUMIFS('무신사 메타 광고'!$U:$U, '무신사 메타 광고'!$D:$D, $B28),SUMIFS('무신사 메타 광고'!$U:$U,'무신사 메타 광고'!$I:$I,$C$4,'무신사 메타 광고'!$D:$D,$B28)) -> 11 | J28: =IFERROR( I28/H28,0) -> 0.027363184 | K28: =IFERROR(H28/G28,0) -> 0.021879933 | L28: =IF( IFERROR(IF(K27=0, 0, (K28 - K27) / K27), 0)=0," ",IFERROR(IF(K27=0, 0, (K28 - K27) / K27), 0)) -> -0.094312608 | N28: =IF($C$4="", SUMIFS('무신사 메타 광고'!$X:$X, '무신사 메타 광고'!$D:$D, $B28),SUMIFS('무신사 메타 광고'!$X:$X,'무신사 메타 광고'!I:I,$C$4,'무신사 메타 광고'!D:D,$B28)) -> 8806100 | O28: =IFERROR( N28/(N28+D28),0 ) -> 0.88127536 | S28: =IF($S$4="", SUMIFS('무신사 메타 광고'!$L:$L, '무신사 메타 광고'!$C:$C, $R28),SUMIFS('무신사 메타 광고'!L:L,'무신사 메타 광고'!$I:$I,$S$4,'무신사 메타 광고'!$C:$C,$R28)) -> 0 | T28: =IF($S$4="", SUMIFS('무신사 메타 광고'!$V:$V, '무신사 메타 광고'!$C:$C, $R28),SUMIFS('무신사 메타 광고'!$V:$V,'무신사 메타 광고'!$I:$I,$S$4,'무신사 메타 광고'!$C:$C,$R28)) -> 0 | U28: =IFERROR(T28/S28,0) -> 0 | V28: =IF( IFERROR(IF(U27=0, 0, (U28 - U27) / U27), 0)=0," ",IFERROR(IF(U27=0, 0, (U28 - U27) / U27), 0)) | W28: =IF($S$4="", SUMIFS('무신사 메타 광고'!$K:$K, '무신사 메타 광고'!$C:$C, $R28),SUMIFS('무신사 메타 광고'!$K:$K,'무신사 메타 광고'!$I:$I,$S$4,'무신사 메타 광고'!$C:$C,$R28)) -> 0 | X28: =IF($S$4="", SUMIFS('무신사 메타 광고'!$N:$N, '무신사 메타 광고'!$C:$C, $R28),SUMIFS('무신사 메타 광고'!$N:$N,'무신사 메타 광고'!$I:$I,$S$4,'무신사 메타 광고'!$C:$C,$R28)) -> 0 | Y28: =IFERROR(X28/W28,0) -> 0 | Z28: =IF( IFERROR(IF(Y27=0, 0, (Y28 - Y27) / Y27), 0)=0," ",IFERROR(IF(Y27=0, 0, (Y28 - Y27) / Y27), 0)) | AB28: =IF($S$4="", SUMIFS('무신사 메타 광고'!$X:$X, '무신사 메타 광고'!$C:$C, $R28),SUMIFS('무신사 메타 광고'!$X:$X,'무신사 메타 광고'!$I:$I,$S$4,'무신사 메타 광고'!$C:$C,$R28)) -> 0 | AC28: =IFERROR( AB28/(AB28+T28),0 ) -> 0
